<sdf version='1.6'>
  <world name='default'>
    <light name='sun' type='directional'>
      <cast_shadows>1</cast_shadows>
      <pose frame=''>0 0 10 0 -0 0</pose>
      <diffuse>0.8 0.8 0.8 1</diffuse>
      <specular>0.2 0.2 0.2 1</specular>
      <attenuation>
        <range>1000</range>
        <constant>0.9</constant>
        <linear>0.01</linear>
        <quadratic>0.001</quadratic>
      </attenuation>
      <direction>-0.5 0.1 -0.9</direction>
    </light>
    <model name='ground_plane'>
      <static>1</static>
      <link name='link'>
        <collision name='collision'>
          <geometry>
            <plane>
              <normal>0 0 1</normal>
              <size>100 100</size>
            </plane>
          </geometry>
          <surface>
            <contact>
              <collide_bitmask>65535</collide_bitmask>
              <ode/>
            </contact>
            <friction>
              <ode>
                <mu>100</mu>
                <mu2>50</mu2>
              </ode>
              <torsional>
                <ode/>
              </torsional>
            </friction>
            <bounce/>
          </surface>
          <max_contacts>10</max_contacts>
        </collision>
        <visual name='visual'>
          <cast_shadows>0</cast_shadows>
          <geometry>
            <plane>
              <normal>0 0 1</normal>
              <size>100 100</size>
            </plane>
          </geometry>
          <material>
            <script>
              <uri>file://media/materials/scripts/gazebo.material</uri>
              <name>Gazebo/Grey</name>
            </script>
          </material>
        </visual>
        <self_collide>0</self_collide>
        <enable_wind>0</enable_wind>
        <kinematic>0</kinematic>
      </link>
    </model>
    <model name='asphalt_plane'>
      <static>1</static>
      <link name='link'>
        <collision name='collision'>
          <geometry>
            <box>
              <size>200 200 0.1</size>
            </box>
          </geometry>
          <max_contacts>10</max_contacts>
          <surface>
            <contact>
              <ode/>
            </contact>
            <bounce/>
            <friction>
              <torsional>
                <ode/>
              </torsional>
              <ode/>
            </friction>
          </surface>
        </collision>
        <visual name='visual'>
          <cast_shadows>0</cast_shadows>
          <geometry>
            <box>
              <size>200 200 0.1</size>
            </box>
          </geometry>
          <material>
            <script>
              <uri>model://asphalt_plane/materials/scripts</uri>
              <uri>model://asphalt_plane/materials/textures</uri>
              <name>vrc/asphalt</name>
            </script>
          </material>
        </visual>
        <self_collide>0</self_collide>
        <enable_wind>0</enable_wind>
        <kinematic>0</kinematic>
      </link>
    </model>
    <plugin name='wind_plugin' filename='libgazebo_wind_plugin.so'>
      <frameId>base_link</frameId>
      <robotNamespace/>
      <windVelocityMean>1.0</windVelocityMean>
      <windVelocityMax>2.5</windVelocityMax>
      <windVelocityVariance>1</windVelocityVariance>
      <windDirectionMean>0 1 0</windDirectionMean>
      <windDirectionVariance>1</windDirectionVariance>
      <windGustStart>0</windGustStart>
      <windGustDuration>0</windGustDuration>
      <windGustVelocityMean>0</windGustVelocityMean>
      <windGustVelocityMax>2.0</windGustVelocityMax>
      <windGustVelocityVariance>1</windGustVelocityVariance>
      <windGustDirectionMean>1 0 0</windGustDirectionMean>
      <windGustDirectionVariance>1</windGustDirectionVariance>
      <windPubTopic>world_wind</windPubTopic>
      <publishRate>1</publishRate>
    </plugin>
    <physics name='default_physics' default='0' type='ode'>
      <ode>
        <solver>
          <type>quick</type>
          <iters>10</iters>
          <sor>1.3</sor>
          <use_dynamic_moi_rescaling>0</use_dynamic_moi_rescaling>
        </solver>
        <constraints>
          <cfm>0</cfm>
          <erp>0.2</erp>
          <contact_max_correcting_vel>100</contact_max_correcting_vel>
          <contact_surface_layer>0.001</contact_surface_layer>
        </constraints>
      </ode>
      <max_step_size>0.004</max_step_size>
      <real_time_factor>1</real_time_factor>
      <real_time_update_rate>250</real_time_update_rate>
    </physics>
    <gravity>0 0 -9.8066</gravity>
    <magnetic_field>6e-06 2.3e-05 -4.2e-05</magnetic_field>
    <atmosphere type='adiabatic'/>
    <scene>
      <ambient>0.4 0.4 0.4 1</ambient>
      <background>0.7 0.7 0.7 1</background>
      <shadows>1</shadows>
    </scene>
    <audio>
      <device>default</device>
    </audio>
    <wind/>
    <spherical_coordinates>
      <surface_model>EARTH_WGS84</surface_model>
      <latitude_deg>0</latitude_deg>
      <longitude_deg>0</longitude_deg>
      <elevation>0</elevation>
      <heading_deg>0</heading_deg>
    </spherical_coordinates>
    <model name='gemini2'>
      <pose frame=''>1.01 0.98 0.83 0 -0 0</pose>
      <link name='base_link'>
        <pose frame=''>0 0 0 0 -0 0</pose>
        <inertial>
          <pose frame=''>0 0 0 0 -0 0</pose>
          <mass>1.5</mass>
          <inertia>
            <ixx>0.197563</ixx>
            <ixy>0</ixy>
            <ixz>0</ixz>
            <iyy>0.145893</iyy>
            <iyz>0</iyz>
            <izz>0.1477</izz>
          </inertia>
        </inertial>
        <collision name='base_link_collision'>
          <pose frame=''>0 0 -0.07 0 -0 0</pose>
          <geometry>
            <box>
              <size>0.47 0.47 0.11</size>
            </box>
          </geometry>
          <surface>
            <contact>
              <ode>
                <max_vel>10</max_vel>
                <min_depth>0.01</min_depth>
              </ode>
            </contact>
            <bounce/>
            <friction>
              <torsional>
                <ode/>
              </torsional>
              <ode/>
            </friction>
          </surface>
          <max_contacts>10</max_contacts>
        </collision>
        <visual name='base_link_visual'>
          <pose frame=''>0.07 0 -0.08 0 -0 0</pose>
          <geometry>
            <mesh>
              <scale>0.1 0.1 0.1</scale>
              <uri>model://gemini2/meshes/body.dae</uri>
            </mesh>
          </geometry>
          <material>
            <script>
              <name>Gazebo/DarkGrey</name>
              <uri>__default__</uri>
            </script>
          </material>
        </visual>
        <gravity>1</gravity>
        <velocity_decay/>
        <self_collide>0</self_collide>
        <enable_wind>0</enable_wind>
        <kinematic>0</kinematic>
      </link>
      <link name='gemini2/imu_link'>
        <pose frame=''>0 0 0 0 -0 0</pose>
        <inertial>
          <pose frame=''>0 0 0 0 -0 0</pose>
          <mass>0.015</mass>
          <inertia>
            <ixx>1e-05</ixx>
            <ixy>0</ixy>
            <ixz>0</ixz>
            <iyy>1e-05</iyy>
            <iyz>0</iyz>
            <izz>1e-05</izz>
          </inertia>
        </inertial>
        <self_collide>0</self_collide>
        <enable_wind>0</enable_wind>
        <kinematic>0</kinematic>
      </link>
      <joint name='gemini2/imu_joint' type='revolute'>
        <child>gemini2/imu_link</child>
        <parent>base_link</parent>
        <axis>
          <xyz>1 0 0</xyz>
          <limit>
            <lower>0</lower>
            <upper>0</upper>
            <effort>0</effort>
            <velocity>0</velocity>
          </limit>
          <dynamics>
            <spring_reference>0</spring_reference>
            <spring_stiffness>0</spring_stiffness>
          </dynamics>
          <use_parent_model_frame>1</use_parent_model_frame>
        </axis>
      </joint>
      <link name='airspeed::link'>
        <pose frame=''>0 0 0 0 -0 0</pose>
        <inertial>
          <pose frame=''>0 0 0 0 -0 0</pose>
          <mass>0.015</mass>
          <inertia>
            <ixx>1e-05</ixx>
            <ixy>0</ixy>
            <ixz>0</ixz>
            <iyy>1e-05</iyy>
            <iyz>0</iyz>
            <izz>1e-05</izz>
          </inertia>
        </inertial>
        <visual name='visual'>
          <geometry>
            <cylinder>
              <radius>0.01</radius>
              <length>0.1</length>
            </cylinder>
          </geometry>
          <material>
            <script>
              <name>Gazebo/Black</name>
              <uri>__default__</uri>
            </script>
          </material>
        </visual>
        <sensor name='airspeed' type='gps'>
          <pose frame=''>0 0 0 0 -0 0</pose>
          <update_rate>5</update_rate>
          <always_on>1</always_on>
          <visualize>0</visualize>
          <plugin name='airspeed_plugin' filename='libgazebo_airspeed_plugin.so'>
            <robotNamespace/>
          </plugin>
          <gps/>
        </sensor>
        <self_collide>0</self_collide>
        <enable_wind>0</enable_wind>
        <kinematic>0</kinematic>
      </link>
      <joint name='airspeed_joint' type='fixed'>
        <child>airspeed::link</child>
        <parent>base_link</parent>
      </joint>
      <link name='rotor_puller'>
        <pose frame=''>0.3 0 0 0 1.57 0</pose>
        <inertial>
          <pose frame=''>0 0 0 0 -0 0</pose>
          <mass>0.005</mass>
          <inertia>
            <ixx>9.75e-07</ixx>
            <ixy>0</ixy>
            <ixz>0</ixz>
            <iyy>0.000166704</iyy>
            <iyz>0</iyz>
            <izz>0.000167604</izz>
          </inertia>
        </inertial>
        <collision name='rotor_puller_collision'>
          <pose frame=''>0 0 0 0 -0 0</pose>
          <geometry>
            <cylinder>
              <length>0.005</length>
              <radius>0.1</radius>
            </cylinder>
          </geometry>
          <surface>
            <contact>
              <ode/>
            </contact>
            <friction>
              <ode/>
              <torsional>
                <ode/>
              </torsional>
            </friction>
            <bounce/>
          </surface>
          <max_contacts>10</max_contacts>
        </collision>
        <visual name='rotor_puller_visual'>
          <pose frame=''>0 0 -0.09 0 -0 0</pose>
          <geometry>
            <mesh>
              <scale>1 1 1</scale>
              <uri>model://gemini2/meshes/iris_prop_ccw.dae</uri>
            </mesh>
          </geometry>
          <material>
            <script>
              <name>Gazebo/Blue</name>
              <uri>__default__</uri>
            </script>
          </material>
        </visual>
        <gravity>1</gravity>
        <velocity_decay/>
        <self_collide>0</self_collide>
        <enable_wind>0</enable_wind>
        <kinematic>0</kinematic>
      </link>
      <joint name='rotor_puller_joint' type='revolute'>
        <child>rotor_puller</child>
        <parent>base_link</parent>
        <axis>
          <xyz>1 0 0</xyz>
          <limit>
            <lower>-1e+16</lower>
            <upper>1e+16</upper>
          </limit>
          <dynamics>
            <spring_reference>0</spring_reference>
            <spring_stiffness>0</spring_stiffness>
          </dynamics>
          <use_parent_model_frame>1</use_parent_model_frame>
        </axis>
      </joint>
      <link name='left_elevon'>
        <inertial>
          <mass>1e-08</mass>
          <inertia>
            <ixx>1e-06</ixx>
            <ixy>0</ixy>
            <iyy>1e-06</iyy>
            <ixz>0</ixz>
            <iyz>0</iyz>
            <izz>1e-06</izz>
          </inertia>
          <pose frame=''>0 0.3 0 0 -0 0</pose>
        </inertial>
        <visual name='left_elevon_visual'>
          <pose frame=''>0.07 0 -0.08 0 -0 0</pose>
          <geometry>
            <mesh>
              <scale>0.1 0.1 0.1</scale>
              <uri>model://gemini2/meshes/left_aileron.dae</uri>
            </mesh>
          </geometry>
          <material>
            <script>
              <name>Gazebo/Blue</name>
              <uri>__default__</uri>
            </script>
          </material>
          <plugin name='left_elevon_lift_visual' filename='libForceVisual.so'>
            <topic_name>lift_force/left_elevon</topic_name>
            <color>Gazebo/Red</color>
          </plugin>
        </visual>
        <self_collide>0</self_collide>
        <enable_wind>0</enable_wind>
        <kinematic>0</kinematic>
      </link>
      <link name='right_elevon'>
        <inertial>
          <mass>1e-08</mass>
          <inertia>
            <ixx>1e-06</ixx>
            <ixy>0</ixy>
            <iyy>1e-06</iyy>
            <ixz>0</ixz>
            <iyz>0</iyz>
            <izz>1e-06</izz>
          </inertia>
          <pose frame=''>0 -0.3 0 0 -0 0</pose>
        </inertial>
        <visual name='right_elevon_visual'>
          <pose frame=''>0.07 0 -0.08 0 -0 0</pose>
          <geometry>
            <mesh>
              <scale>0.1 0.1 0.1</scale>
              <uri>model://gemini2/meshes/right_aileron.dae</uri>
            </mesh>
          </geometry>
          <material>
            <script>
              <name>Gazebo/Blue</name>
              <uri>__default__</uri>
            </script>
          </material>
          <plugin name='right_elevon_lift_visual' filename='libForceVisual.so'>
            <topic_name>lift_force/right_elevon</topic_name>
            <color>Gazebo/Green</color>
          </plugin>
        </visual>
        <self_collide>0</self_collide>
        <enable_wind>0</enable_wind>
        <kinematic>0</kinematic>
      </link>
      <link name='left_flap'>
        <inertial>
          <mass>1e-08</mass>
          <inertia>
            <ixx>1e-06</ixx>
            <ixy>0</ixy>
            <iyy>1e-06</iyy>
            <ixz>0</ixz>
            <iyz>0</iyz>
            <izz>1e-06</izz>
          </inertia>
          <pose frame=''>0 0.15 0 0 -0 0</pose>
        </inertial>
        <visual name='left_flap_visual'>
          <pose frame=''>0.07 0 -0.08 0 -0 0</pose>
          <geometry>
            <mesh>
              <scale>0.1 0.1 0.1</scale>
              <uri>model://gemini2/meshes/left_flap.dae</uri>
            </mesh>
          </geometry>
          <material>
            <script>
              <name>Gazebo/Blue</name>
              <uri>__default__</uri>
            </script>
          </material>
        </visual>
        <self_collide>0</self_collide>
        <enable_wind>0</enable_wind>
        <kinematic>0</kinematic>
      </link>
      <link name='right_flap'>
        <inertial>
          <mass>1e-08</mass>
          <inertia>
            <ixx>1e-06</ixx>
            <ixy>0</ixy>
            <iyy>1e-06</iyy>
            <ixz>0</ixz>
            <iyz>0</iyz>
            <izz>1e-06</izz>
          </inertia>
          <pose frame=''>0 -0.15 0 0 -0 0</pose>
        </inertial>
        <visual name='right_flap_visual'>
          <pose frame=''>0.07 0 -0.08 0 -0 0</pose>
          <geometry>
            <mesh>
              <scale>0.1 0.1 0.1</scale>
              <uri>model://gemini2/meshes/right_flap.dae</uri>
            </mesh>
          </geometry>
          <material>
            <script>
              <name>Gazebo/Blue</name>
              <uri>__default__</uri>
            </script>
          </material>
        </visual>
        <self_collide>0</self_collide>
        <enable_wind>0</enable_wind>
        <kinematic>0</kinematic>
      </link>
      <link name='elevator'>
        <inertial>
          <mass>1e-08</mass>
          <inertia>
            <ixx>1e-06</ixx>
            <ixy>0</ixy>
            <iyy>1e-06</iyy>
            <ixz>0</ixz>
            <iyz>0</iyz>
            <izz>1e-06</izz>
          </inertia>
          <pose frame=''>-0.5 0 0 0 -0 0</pose>
        </inertial>
        <visual name='elevator_visual'>
          <pose frame=''>0.07 0 -0.08 0 -0 0</pose>
          <geometry>
            <mesh>
              <scale>0.1 0.1 0.1</scale>
              <uri>model://gemini2/meshes/elevators.dae</uri>
            </mesh>
          </geometry>
          <material>
            <script>
              <name>Gazebo/Blue</name>
              <uri>__default__</uri>
            </script>
          </material>
        </visual>
        <self_collide>0</self_collide>
        <enable_wind>0</enable_wind>
        <kinematic>0</kinematic>
      </link>
      <link name='rudder'>
        <inertial>
          <mass>1e-08</mass>
          <inertia>
            <ixx>1e-06</ixx>
            <ixy>0</ixy>
            <iyy>1e-06</iyy>
            <ixz>0</ixz>
            <iyz>0</iyz>
            <izz>1e-06</izz>
          </inertia>
          <pose frame=''>-0.5 0 0.05 0 -0 0</pose>
        </inertial>
        <visual name='rudder_visual'>
          <pose frame=''>0.07 0 -0.08 0 -0 0</pose>
          <geometry>
            <mesh>
              <scale>0.1 0.1 0.1</scale>
              <uri>model://gemini2/meshes/rudder.dae</uri>
            </mesh>
          </geometry>
          <material>
            <script>
              <name>Gazebo/Blue</name>
              <uri>__default__</uri>
            </script>
          </material>
        </visual>
        <self_collide>0</self_collide>
        <enable_wind>0</enable_wind>
        <kinematic>0</kinematic>
      </link>
      <joint name='left_elevon_joint' type='revolute'>
        <parent>base_link</parent>
        <child>left_elevon</child>
        <pose frame=''>-0.07 0.4 0.08 0 -0 0</pose>
        <axis>
          <xyz>0 1 0</xyz>
          <limit>
            <lower>-0.53</lower>
            <upper>0.53</upper>
          </limit>
          <dynamics>
            <damping>1</damping>
            <spring_reference>0</spring_reference>
            <spring_stiffness>0</spring_stiffness>
          </dynamics>
          <use_parent_model_frame>0</use_parent_model_frame>
        </axis>
        <physics>
          <ode>
            <implicit_spring_damper>1</implicit_spring_damper>
            <limit>
              <cfm>0</cfm>
              <erp>0.2</erp>
            </limit>
          </ode>
        </physics>
      </joint>
      <joint name='right_elevon_joint' type='revolute'>
        <parent>base_link</parent>
        <child>right_elevon</child>
        <pose frame=''>-0.07 -0.4 0.08 0 -0 0</pose>
        <axis>
          <xyz>0 1 0</xyz>
          <limit>
            <lower>-0.53</lower>
            <upper>0.53</upper>
          </limit>
          <dynamics>
            <damping>1</damping>
            <spring_reference>0</spring_reference>
            <spring_stiffness>0</spring_stiffness>
          </dynamics>
          <use_parent_model_frame>0</use_parent_model_frame>
        </axis>
        <physics>
          <ode>
            <implicit_spring_damper>1</implicit_spring_damper>
            <limit>
              <cfm>0</cfm>
              <erp>0.2</erp>
            </limit>
          </ode>
        </physics>
      </joint>
      <joint name='left_flap_joint' type='revolute'>
        <parent>base_link</parent>
        <child>left_flap</child>
        <pose frame=''>-0.07 0.2 0.08 0 -0 0</pose>
        <axis>
          <xyz>0 1 0</xyz>
          <limit>
            <lower>-0.53</lower>
            <upper>0.53</upper>
          </limit>
          <dynamics>
            <damping>1</damping>
            <spring_reference>0</spring_reference>
            <spring_stiffness>0</spring_stiffness>
          </dynamics>
          <use_parent_model_frame>0</use_parent_model_frame>
        </axis>
        <physics>
          <ode>
            <implicit_spring_damper>1</implicit_spring_damper>
            <limit>
              <cfm>0</cfm>
              <erp>0.2</erp>
            </limit>
          </ode>
        </physics>
      </joint>
      <joint name='right_flap_joint' type='revolute'>
        <parent>base_link</parent>
        <child>right_flap</child>
        <pose frame=''>-0.07 -0.2 0.08 0 -0 0</pose>
        <axis>
          <xyz>0 1 0</xyz>
          <limit>
            <lower>-0.53</lower>
            <upper>0.53</upper>
          </limit>
          <dynamics>
            <damping>1</damping>
            <spring_reference>0</spring_reference>
            <spring_stiffness>0</spring_stiffness>
          </dynamics>
          <use_parent_model_frame>0</use_parent_model_frame>
        </axis>
        <physics>
          <ode>
            <implicit_spring_damper>1</implicit_spring_damper>
            <limit>
              <cfm>0</cfm>
              <erp>0.2</erp>
            </limit>
          </ode>
        </physics>
      </joint>
      <joint name='elevator_joint' type='revolute'>
        <parent>base_link</parent>
        <child>elevator</child>
        <pose frame=''>-0.5 0 0 0 -0 0</pose>
        <axis>
          <xyz>0 1 0</xyz>
          <limit>
            <lower>-0.53</lower>
            <upper>0.53</upper>
          </limit>
          <dynamics>
            <damping>1</damping>
            <spring_reference>0</spring_reference>
            <spring_stiffness>0</spring_stiffness>
          </dynamics>
          <use_parent_model_frame>0</use_parent_model_frame>
        </axis>
        <physics>
          <ode>
            <implicit_spring_damper>1</implicit_spring_damper>
            <limit>
              <cfm>0</cfm>
              <erp>0.2</erp>
            </limit>
          </ode>
        </physics>
      </joint>
      <joint name='rudder_joint' type='revolute'>
        <parent>base_link</parent>
        <child>rudder</child>
        <pose frame=''>-0.5 0 0.05 0 -0 0</pose>
        <axis>
          <xyz>0 0 1</xyz>
          <limit>
            <lower>-0.53</lower>
            <upper>0.53</upper>
          </limit>
          <dynamics>
            <damping>1</damping>
            <spring_reference>0</spring_reference>
            <spring_stiffness>0</spring_stiffness>
          </dynamics>
          <use_parent_model_frame>0</use_parent_model_frame>
        </axis>
        <physics>
          <ode>
            <implicit_spring_damper>1</implicit_spring_damper>
            <limit>
              <cfm>0</cfm>
              <erp>0.2</erp>
            </limit>
          </ode>
        </physics>
      </joint>
      <link name='gps::link'>
        <pose frame=''>0 0 0 0 -0 0</pose>
        <inertial>
          <pose frame=''>0 0 0 0 -0 0</pose>
          <mass>0.015</mass>
          <inertia>
            <ixx>1e-05</ixx>
            <ixy>0</ixy>
            <ixz>0</ixz>
            <iyy>1e-05</iyy>
            <iyz>0</iyz>
            <izz>1e-05</izz>
          </inertia>
        </inertial>
        <visual name='visual'>
          <geometry>
            <cylinder>
              <radius>0.01</radius>
              <length>0.002</length>
            </cylinder>
          </geometry>
          <material>
            <script>
              <name>Gazebo/Black</name>
              <uri>__default__</uri>
            </script>
          </material>
        </visual>
        <sensor name='gps' type='gps'>
          <pose frame=''>0 0 0 0 -0 0</pose>
          <update_rate>5</update_rate>
          <always_on>1</always_on>
          <visualize>0</visualize>
          <plugin name='gps_plugin' filename='libgazebo_gps_plugin.so'>
            <robotNamespace/>
            <gpsNoise>1</gpsNoise>
            <gpsXYRandomWalk>2.0</gpsXYRandomWalk>
            <gpsZRandomWalk>4.0</gpsZRandomWalk>
            <gpsXYNoiseDensity>2.0e-4</gpsXYNoiseDensity>
            <gpsZNoiseDensity>4.0e-4</gpsZNoiseDensity>
            <gpsVXYNoiseDensity>0.2</gpsVXYNoiseDensity>
            <gpsVZNoiseDensity>0.4</gpsVZNoiseDensity>
          </plugin>
          <gps/>
        </sensor>
        <self_collide>0</self_collide>
        <enable_wind>0</enable_wind>
        <kinematic>0</kinematic>
      </link>
      <joint name='gps_joint' type='fixed'>
        <child>gps::link</child>
        <parent>base_link</parent>
      </joint>
      <plugin name='left_wing' filename='libLiftDragPlugin.so'>
        <a0>0.05984281113</a0>
        <cla>4.752798721</cla>
        <cda>0.6417112299</cda>
        <cma>0.0</cma>
        <alpha_stall>0.3391428111</alpha_stall>
        <cla_stall>-3.85</cla_stall>
        <cda_stall>-0.9233984055</cda_stall>
        <cma_stall>0</cma_stall>
        <cp>-0.05 0.45 0.05</cp>
        <area>0.6</area>
        <air_density>1.2041</air_density>
        <forward>1 0 0</forward>
        <upward>0 0 1</upward>
        <link_name>base_link</link_name>
        <control_joint_name>left_elevon_joint</control_joint_name>
        <control_joint_rad_to_cl>-0.3</control_joint_rad_to_cl>
        <robotNamespace/>
        <windSubTopic>world_wind</windSubTopic>
      </plugin>
      <plugin name='right_wing' filename='libLiftDragPlugin.so'>
        <a0>0.05984281113</a0>
        <cla>4.752798721</cla>
        <cda>0.6417112299</cda>
        <cma>0.0</cma>
        <alpha_stall>0.3391428111</alpha_stall>
        <cla_stall>-3.85</cla_stall>
        <cda_stall>-0.9233984055</cda_stall>
        <cma_stall>0</cma_stall>
        <cp>-0.05 -0.45 0.05</cp>
        <area>0.6</area>
        <air_density>1.2041</air_density>
        <forward>1 0 0</forward>
        <upward>0 0 1</upward>
        <link_name>base_link</link_name>
        <control_joint_name>right_elevon_joint</control_joint_name>
        <control_joint_rad_to_cl>-0.3</control_joint_rad_to_cl>
        <robotNamespace/>
        <windSubTopic>world_wind</windSubTopic>
      </plugin>
      <plugin name='left_flap' filename='libLiftDragPlugin.so'>
        <a0>0.05984281113</a0>
        <cla>4.752798721</cla>
        <cda>0.6417112299</cda>
        <cma>0.0</cma>
        <alpha_stall>0.3391428111</alpha_stall>
        <cla_stall>-3.85</cla_stall>
        <cda_stall>-0.9233984055</cda_stall>
        <cma_stall>0</cma_stall>
        <cp>-0.05 0.15 0.05</cp>
        <area>0.6</area>
        <air_density>1.2041</air_density>
        <forward>1 0 0</forward>
        <upward>0 0 1</upward>
        <link_name>base_link</link_name>
        <control_joint_name>left_flap_joint</control_joint_name>
        <control_joint_rad_to_cl>-0.1</control_joint_rad_to_cl>
        <robotNamespace/>
        <windSubTopic>world_wind</windSubTopic>
      </plugin>
      <plugin name='right_flap' filename='libLiftDragPlugin.so'>
        <a0>0.05984281113</a0>
        <cla>4.752798721</cla>
        <cda>0.6417112299</cda>
        <cma>0.0</cma>
        <alpha_stall>0.3391428111</alpha_stall>
        <cla_stall>-3.85</cla_stall>
        <cda_stall>-0.9233984055</cda_stall>
        <cma_stall>0</cma_stall>
        <cp>-0.05 -0.15 0.05</cp>
        <area>0.6</area>
        <air_density>1.2041</air_density>
        <forward>1 0 0</forward>
        <upward>0 0 1</upward>
        <link_name>base_link</link_name>
        <control_joint_name>right_flap_joint</control_joint_name>
        <control_joint_rad_to_cl>-0.1</control_joint_rad_to_cl>
        <robotNamespace/>
        <windSubTopic>world_wind</windSubTopic>
      </plugin>
      <plugin name='elevator' filename='libLiftDragPlugin.so'>
        <a0>-0.2</a0>
        <cla>4.752798721</cla>
        <cda>0.6417112299</cda>
        <cma>0.0</cma>
        <alpha_stall>0.3391428111</alpha_stall>
        <cla_stall>-3.85</cla_stall>
        <cda_stall>-0.9233984055</cda_stall>
        <cma_stall>0</cma_stall>
        <cp>-0.5 0 0</cp>
        <area>0.01</area>
        <air_density>1.2041</air_density>
        <forward>1 0 0</forward>
        <upward>0 0 1</upward>
        <link_name>base_link</link_name>
        <control_joint_name>elevator_joint</control_joint_name>
        <control_joint_rad_to_cl>-4.0</control_joint_rad_to_cl>
        <robotNamespace/>
        <windSubTopic>world_wind</windSubTopic>
      </plugin>
      <plugin name='rudder' filename='libLiftDragPlugin.so'>
        <a0>0.0</a0>
        <cla>4.752798721</cla>
        <cda>0.6417112299</cda>
        <cma>0.0</cma>
        <alpha_stall>0.3391428111</alpha_stall>
        <cla_stall>-3.85</cla_stall>
        <cda_stall>-0.9233984055</cda_stall>
        <cma_stall>0</cma_stall>
        <cp>-0.5 0 0.05</cp>
        <area>0.02</area>
        <air_density>1.2041</air_density>
        <forward>1 0 0</forward>
        <upward>0 1 0</upward>
        <link_name>base_link</link_name>
        <control_joint_name>rudder_joint</control_joint_name>
        <control_joint_rad_to_cl>0.8</control_joint_rad_to_cl>
        <robotNamespace/>
        <windSubTopic>world_wind</windSubTopic>
      </plugin>
      <plugin name='puller' filename='libgazebo_motor_model.so'>
        <robotNamespace/>
        <jointName>rotor_puller_joint</jointName>
        <linkName>rotor_puller</linkName>
        <turningDirection>cw</turningDirection>
        <timeConstantUp>0.0125</timeConstantUp>
        <timeConstantDown>0.025</timeConstantDown>
        <maxRotVelocity>3500</maxRotVelocity>
        <motorConstant>8.54858e-06</motorConstant>
        <momentConstant>0.01</momentConstant>
        <commandSubTopic>/gazebo/command/motor_speed</commandSubTopic>
        <motorNumber>2</motorNumber>
        <rotorDragCoefficient>8.06428e-05</rotorDragCoefficient>
        <rollingMomentCoefficient>1e-06</rollingMomentCoefficient>
        <motorSpeedPubTopic>/motor_speed/4</motorSpeedPubTopic>
        <rotorVelocitySlowdownSim>10</rotorVelocitySlowdownSim>
        <robotNamespace/>
        <windSubTopic>world_wind</windSubTopic>
      </plugin>
      <plugin name='groundtruth_plugin' filename='libgazebo_groundtruth_plugin.so'>
        <robotNamespace/>
      </plugin>
      <plugin name='magnetometer_plugin' filename='libgazebo_magnetometer_plugin.so'>
        <robotNamespace/>
        <pubRate>100</pubRate>
        <noiseDensity>0.0004</noiseDensity>
        <randomWalk>6.4e-06</randomWalk>
        <biasCorrelationTime>600</biasCorrelationTime>
        <magTopic>/mag</magTopic>
      </plugin>
      <plugin name='barometer_plugin' filename='libgazebo_barometer_plugin.so'>
        <robotNamespace/>
        <pubRate>50</pubRate>
        <baroTopic>/baro</baroTopic>
      </plugin>
      <plugin name='mavlink_interface' filename='libgazebo_mavlink_interface.so'>
        <robotNamespace/>
        <imuSubTopic>/imu</imuSubTopic>
        <magSubTopic>/mag</magSubTopic>
        <baroSubTopic>/baro</baroSubTopic>
        <mavlink_addr>INADDR_ANY</mavlink_addr>
        <mavlink_tcp_port>4560</mavlink_tcp_port>
        <mavlink_udp_port>14560</mavlink_udp_port>
        <serialEnabled>0</serialEnabled>
        <serialDevice>/dev/ttyACM0</serialDevice>
        <baudRate>921600</baudRate>
        <qgc_addr>INADDR_ANY</qgc_addr>
        <qgc_udp_port>14550</qgc_udp_port>
        <sdk_addr>INADDR_ANY</sdk_addr>
        <sdk_udp_port>14540</sdk_udp_port>
        <hil_mode>0</hil_mode>
        <hil_state_level>0</hil_state_level>
        <enable_lockstep>1</enable_lockstep>
        <use_tcp>1</use_tcp>
        <motorSpeedCommandPubTopic>/gazebo/command/motor_speed</motorSpeedCommandPubTopic>
        <control_channels>
          <channel name='rudder'>
            <input_index>3</input_index>
            <input_offset>0</input_offset>
            <input_scaling>-1</input_scaling>
            <zero_position_disarmed>0</zero_position_disarmed>
            <zero_position_armed>0</zero_position_armed>
            <joint_control_type>position_kinematic</joint_control_type>
            <joint_name>rudder_joint</joint_name>
          </channel>
          <channel name='rotor4'>
            <input_index>2</input_index>
            <input_offset>0</input_offset>
            <input_scaling>3500</input_scaling>
            <zero_position_disarmed>0</zero_position_disarmed>
            <zero_position_armed>0</zero_position_armed>
            <joint_control_type>velocity</joint_control_type>
            <joint_name>rotor_puller_joint</joint_name>
          </channel>
          <channel name='left_elevon'>
            <input_index>6</input_index>
            <input_offset>0</input_offset>
            <input_scaling>-1</input_scaling>
            <zero_position_disarmed>0</zero_position_disarmed>
            <zero_position_armed>0</zero_position_armed>
            <joint_control_type>position_kinematic</joint_control_type>
            <joint_name>left_elevon_joint</joint_name>
          </channel>
          <channel name='right_elevon'>
            <input_index>0</input_index>
            <input_offset>0</input_offset>
            <input_scaling>1</input_scaling>
            <zero_position_disarmed>0</zero_position_disarmed>
            <zero_position_armed>0</zero_position_armed>
            <joint_control_type>position_kinematic</joint_control_type>
            <joint_name>right_elevon_joint</joint_name>
          </channel>
          <channel name='elevator'>
            <input_index>1</input_index>
            <input_offset>0</input_offset>
            <input_scaling>1</input_scaling>
            <zero_position_disarmed>0</zero_position_disarmed>
            <zero_position_armed>0</zero_position_armed>
            <joint_control_type>position_kinematic</joint_control_type>
            <joint_name>elevator_joint</joint_name>
          </channel>
          <channel name='left_flap'>
            <input_index>9</input_index>
            <input_offset>0</input_offset>
            <input_scaling>-1</input_scaling>
            <zero_position_disarmed>0</zero_position_disarmed>
            <zero_position_armed>0</zero_position_armed>
            <joint_control_type>position_kinematic</joint_control_type>
            <joint_name>left_flap_joint</joint_name>
          </channel>
          <channel name='right_flap'>
            <input_index>10</input_index>
            <input_offset>0</input_offset>
            <input_scaling>-1</input_scaling>
            <zero_position_disarmed>0</zero_position_disarmed>
            <zero_position_armed>0</zero_position_armed>
            <joint_control_type>position_kinematic</joint_control_type>
            <joint_name>right_flap_joint</joint_name>
          </channel>
        </control_channels>
      </plugin>
      <static>0</static>
      <plugin name='gazebo_imu_plugin' filename='libgazebo_imu_plugin.so'>
        <robotNamespace/>
        <linkName>gemini2/imu_link</linkName>
        <imuTopic>/imu</imuTopic>
        <gyroscopeNoiseDensity>0.0003394</gyroscopeNoiseDensity>
        <gyroscopeRandomWalk>3.8785e-05</gyroscopeRandomWalk>
        <gyroscopeBiasCorrelationTime>1000.0</gyroscopeBiasCorrelationTime>
        <gyroscopeTurnOnBiasSigma>0.0087</gyroscopeTurnOnBiasSigma>
        <accelerometerNoiseDensity>0.004</accelerometerNoiseDensity>
        <accelerometerRandomWalk>0.006</accelerometerRandomWalk>
        <accelerometerBiasCorrelationTime>300.0</accelerometerBiasCorrelationTime>
        <accelerometerTurnOnBiasSigma>0.196</accelerometerTurnOnBiasSigma>
      </plugin>
    </model>
    <state world_name='default'>
      <sim_time>4354 968000000</sim_time>
      <real_time>4359 195004121</real_time>
      <wall_time>1654544878 591747934</wall_time>
      <iterations>1088742</iterations>
      <model name='asphalt_plane'>
        <pose frame=''>0 0 0 0 -0 0</pose>
        <scale>1 1 1</scale>
        <link name='link'>
          <pose frame=''>0 0 0 0 -0 0</pose>
          <velocity>0 0 0 0 -0 0</velocity>
          <acceleration>0 0 0 0 -0 0</acceleration>
          <wrench>0 0 0 0 -0 0</wrench>
        </link>
      </model>
      <model name='ground_plane'>
        <pose frame=''>0 0 0 0 -0 0</pose>
        <scale>1 1 1</scale>
        <link name='link'>
          <pose frame=''>0 0 0 0 -0 0</pose>
          <velocity>0 0 0 0 -0 0</velocity>
          <acceleration>0 0 0 0 -0 0</acceleration>
          <wrench>0 0 0 0 -0 0</wrench>
        </link>
      </model>
      <model name='gemini2'>
        <pose frame=''>1.00103 0.979999 0.165113 -0 0.00048 -1e-06</pose>
        <scale>1 1 1</scale>
        <link name='airspeed::link'>
          <pose frame=''>1.00103 0.979999 0.165113 -0 0.00048 -1e-06</pose>
          <velocity>-0 -0 -1e-06 0 -3e-06 0</velocity>
          <acceleration>-0 0 -0 0 -0 0</acceleration>
          <wrench>-0 0 -0 0 -0 0</wrench>
        </link>
        <link name='base_link'>
          <pose frame=''>1.00103 0.979999 0.165113 -0 0.00048 -1e-06</pose>
          <velocity>-0 -0 -1e-06 0 -3e-06 0</velocity>
          <acceleration>0 0 0 0 -0 0</acceleration>
          <wrench>0 0 0 0 -0 0</wrench>
        </link>
        <link name='elevator'>
          <pose frame=''>1.00103 0.979999 0.165112 -0 0.00048 -1e-06</pose>
          <velocity>-0 -0 2e-05 0 -4.4e-05 0</velocity>
          <acceleration>-8.2e-05 -0 -0.000481 0 -0.011063 0</acceleration>
          <wrench>-0 -0 -0 0 -0 0</wrench>
        </link>
        <link name='gps::link'>
          <pose frame=''>1.00103 0.979999 0.165113 -0 0.00048 -1e-06</pose>
          <velocity>-0 -0 -1e-06 0 -3e-06 0</velocity>
          <acceleration>-0 0 -0 0 -0 0</acceleration>
          <wrench>-0 0 -0 0 -0 0</wrench>
        </link>
        <link name='left_elevon'>
          <pose frame=''>1.00103 0.979999 0.165113 -0 0.00048 -1e-06</pose>
          <velocity>3e-06 -0 2e-06 0 -4.4e-05 0</velocity>
          <acceleration>0.000752 -0 0.000575 0 -0.011073 0</acceleration>
          <wrench>0 -0 0 0 -0 0</wrench>
        </link>
        <link name='left_flap'>
          <pose frame=''>1.00103 0.979999 0.165113 -0 0.00048 -1e-06</pose>
          <velocity>3e-06 -0 2e-06 0 -4.4e-05 0</velocity>
          <acceleration>0.000752 -0 0.000575 0 -0.011074 0</acceleration>
          <wrench>0 -0 0 0 -0 0</wrench>
        </link>
        <link name='gemini2/imu_link'>
          <pose frame=''>1.00103 0.979999 0.165113 -0 0.00048 -1e-06</pose>
          <velocity>-0 -0 -1e-06 3e-05 -3e-06 -0</velocity>
          <acceleration>-0 0 -0 0.021211 0 -1e-05</acceleration>
          <wrench>-0 0 -0 0 -0 0</wrench>
        </link>
        <link name='right_elevon'>
          <pose frame=''>1.00103 0.979999 0.165113 -0 0.00048 -1e-06</pose>
          <velocity>3e-06 -0 2e-06 0 -4.4e-05 0</velocity>
          <acceleration>0.000752 -0 0.000575 0 -0.011079 0</acceleration>
          <wrench>0 -0 0 0 -0 0</wrench>
        </link>
        <link name='right_flap'>
          <pose frame=''>1.00103 0.979999 0.165113 -0 0.00048 -1e-06</pose>
          <velocity>3e-06 -0 2e-06 0 -4.4e-05 0</velocity>
          <acceleration>0.000752 -0 0.000575 0 -0.011077 0</acceleration>
          <wrench>0 -0 0 0 -0 0</wrench>
        </link>
        <link name='rotor_puller'>
          <pose frame=''>1.30103 0.979999 0.164969 0.000156 1.57048 0.000155</pose>
          <velocity>-0 -0 0 0 -3e-06 0</velocity>
          <acceleration>-0 0 -0 0 -0 0</acceleration>
          <wrench>-0 0 -0 0 -0 0</wrench>
        </link>
        <link name='rudder'>
          <pose frame=''>1.00103 0.979999 0.165113 0 0.00048 -2e-06</pose>
          <velocity>-0 -0 -1e-06 0 -3e-06 0</velocity>
          <acceleration>-0.000115 -0 -0.000481 0 -0.000655 -1.2e-05</acceleration>
          <wrench>-0 -0 -0 0 -0 0</wrench>
        </link>
      </model>
      <light name='sun'>
        <pose frame=''>0 0 10 0 -0 0</pose>
      </light>
    </state>
    <gui fullscreen='0'>
      <camera name='user_camera'>
        <pose frame=''>8.73263 -0.174128 1.86523 0 0.319643 -3.139</pose>
        <view_controller>orbit</view_controller>
        <projection_type>perspective</projection_type>
      </camera>
    </gui>
  </world>
</sdf>
