<sdf version='1.6'>
  <world name='default'>
    <light name='sun' type='directional'>
      <cast_shadows>1</cast_shadows>
      <pose frame=''>0 0 10 0 -0 0</pose>
      <diffuse>0.8 0.8 0.8 1</diffuse>
      <specular>0.2 0.2 0.2 1</specular>
      <attenuation>
        <range>1000</range>
        <constant>0.9</constant>
        <linear>0.01</linear>
        <quadratic>0.001</quadratic>
      </attenuation>
      <direction>-0.5 0.1 -0.9</direction>
    </light>
    <model name='ground_plane'>
      <static>1</static>
      <link name='link'>
        <collision name='collision'>
          <geometry>
            <plane>
              <normal>0 0 1</normal>
              <size>100 100</size>
            </plane>
          </geometry>
          <surface>
            <contact>
              <collide_bitmask>65535</collide_bitmask>
              <ode/>
            </contact>
            <friction>
              <ode>
                <mu>100</mu>
                <mu2>50</mu2>
              </ode>
              <torsional>
                <ode/>
              </torsional>
            </friction>
            <bounce/>
          </surface>
          <max_contacts>10</max_contacts>
        </collision>
        <visual name='visual'>
          <cast_shadows>0</cast_shadows>
          <geometry>
            <plane>
              <normal>0 0 1</normal>
              <size>100 100</size>
            </plane>
          </geometry>
          <material>
            <script>
              <uri>file://media/materials/scripts/gazebo.material</uri>
              <name>Gazebo/Grey</name>
            </script>
          </material>
        </visual>
        <self_collide>0</self_collide>
        <enable_wind>0</enable_wind>
        <kinematic>0</kinematic>
      </link>
    </model>
    <gravity>0 0 -9.8</gravity>
    <magnetic_field>6e-06 2.3e-05 -4.2e-05</magnetic_field>
    <atmosphere type='adiabatic'/>
    <physics name='default_physics' default='0' type='ode'>
      <max_step_size>0.001</max_step_size>
      <real_time_factor>1</real_time_factor>
      <real_time_update_rate>1000</real_time_update_rate>
    </physics>
    <scene>
      <ambient>0.4 0.4 0.4 1</ambient>
      <background>0.7 0.7 0.7 1</background>
      <shadows>1</shadows>
    </scene>
    <audio>
      <device>default</device>
    </audio>
    <wind/>
    <spherical_coordinates>
      <surface_model>EARTH_WGS84</surface_model>
      <latitude_deg>0</latitude_deg>
      <longitude_deg>0</longitude_deg>
      <elevation>0</elevation>
      <heading_deg>0</heading_deg>
    </spherical_coordinates>
    <model name='px4vision'>
      <link name='base_link'>
        <pose frame=''>0 0 0 0 -0 0</pose>
        <inertial>
          <pose frame=''>0 0 0 0 -0 0</pose>
          <mass>1.5</mass>
          <inertia>
            <ixx>0.029125</ixx>
            <ixy>0</ixy>
            <ixz>0</ixz>
            <iyy>0.029125</iyy>
            <iyz>0</iyz>
            <izz>0.055225</izz>
          </inertia>
        </inertial>
        <collision name='base_link_inertia_collision'>
          <pose frame=''>0 0 0 0 -0 0</pose>
          <geometry>
            <box>
              <size>0.47 0.47 0.11</size>
            </box>
          </geometry>
          <surface>
            <contact>
              <ode>
                <min_depth>0.001</min_depth>
                <max_vel>0</max_vel>
              </ode>
            </contact>
            <friction>
              <ode/>
              <torsional>
                <ode/>
              </torsional>
            </friction>
            <bounce/>
          </surface>
          <max_contacts>10</max_contacts>
        </collision>
        <visual name='base_link_inertia_visual'>
          <pose frame=''>0 0 0 1.5707 0 -0.01</pose>
          <geometry>
            <mesh>
              <scale>0.001 0.001 0.001</scale>
              <uri>model://px4vision/meshes/body.dae</uri>
            </mesh>
          </geometry>
          <material>
            <script>
              <name>Gazebo/DarkGrey</name>
              <uri>file://media/materials/scripts/gazebo.material</uri>
            </script>
          </material>
        </visual>
        <gravity>1</gravity>
        <velocity_decay/>
        <self_collide>0</self_collide>
        <enable_wind>0</enable_wind>
        <kinematic>0</kinematic>
      </link>
      <link name='/imu_link'>
        <pose frame=''>0 0 0 0 -0 0</pose>
        <inertial>
          <pose frame=''>0 0 0 0 -0 0</pose>
          <mass>0.015</mass>
          <inertia>
            <ixx>1e-05</ixx>
            <ixy>0</ixy>
            <ixz>0</ixz>
            <iyy>1e-05</iyy>
            <iyz>0</iyz>
            <izz>1e-05</izz>
          </inertia>
        </inertial>
        <self_collide>0</self_collide>
        <enable_wind>0</enable_wind>
        <kinematic>0</kinematic>
      </link>
      <joint name='/imu_joint' type='revolute'>
        <child>/imu_link</child>
        <parent>base_link</parent>
        <axis>
          <xyz>1 0 0</xyz>
          <limit>
            <lower>0</lower>
            <upper>0</upper>
            <effort>0</effort>
            <velocity>0</velocity>
          </limit>
          <dynamics>
            <spring_reference>0</spring_reference>
            <spring_stiffness>0</spring_stiffness>
          </dynamics>
          <use_parent_model_frame>1</use_parent_model_frame>
        </axis>
      </joint>
      <link name='rotor_0'>
        <pose frame=''>0.0935 -0.107 0.03 0 -0 0</pose>
        <inertial>
          <pose frame=''>0 0 0 0 -0 0</pose>
          <mass>0.005</mass>
          <inertia>
            <ixx>9.75e-07</ixx>
            <ixy>0</ixy>
            <ixz>0</ixz>
            <iyy>0.000273104</iyy>
            <iyz>0</iyz>
            <izz>0.000274004</izz>
          </inertia>
        </inertial>
        <collision name='rotor_0_collision'>
          <pose frame=''>0 0 0 0 -0 0</pose>
          <geometry>
            <cylinder>
              <length>0.005</length>
              <radius>0.128</radius>
            </cylinder>
          </geometry>
          <surface>
            <contact>
              <ode/>
            </contact>
            <friction>
              <ode/>
              <torsional>
                <ode/>
              </torsional>
            </friction>
            <bounce/>
          </surface>
          <max_contacts>10</max_contacts>
        </collision>
        <visual name='rotor_0_visual'>
          <pose frame=''>0 0 0 0 -0 0</pose>
          <geometry>
            <mesh>
              <scale>0.6 0.6 0.6</scale>
              <uri>model://iris/meshes/iris_prop_ccw.dae</uri>
            </mesh>
          </geometry>
          <material>
            <script>
              <name>Gazebo/Blue</name>
              <uri>file://media/materials/scripts/gazebo.material</uri>
            </script>
          </material>
        </visual>
        <gravity>1</gravity>
        <velocity_decay/>
        <self_collide>0</self_collide>
        <enable_wind>0</enable_wind>
        <kinematic>0</kinematic>
      </link>
      <joint name='rotor_0_joint' type='revolute'>
        <child>rotor_0</child>
        <parent>base_link</parent>
        <axis>
          <xyz>0 0 1</xyz>
          <limit>
            <lower>-1e+16</lower>
            <upper>1e+16</upper>
          </limit>
          <dynamics>
            <spring_reference>0</spring_reference>
            <spring_stiffness>0</spring_stiffness>
          </dynamics>
          <use_parent_model_frame>1</use_parent_model_frame>
        </axis>
      </joint>
      <link name='rotor_1'>
        <pose frame=''>-0.0935 0.107 0.03 0 -0 0</pose>
        <inertial>
          <pose frame=''>0 0 0 0 -0 0</pose>
          <mass>0.005</mass>
          <inertia>
            <ixx>9.75e-07</ixx>
            <ixy>0</ixy>
            <ixz>0</ixz>
            <iyy>0.000273104</iyy>
            <iyz>0</iyz>
            <izz>0.000274004</izz>
          </inertia>
        </inertial>
        <collision name='rotor_1_collision'>
          <pose frame=''>0 0 0 0 -0 0</pose>
          <geometry>
            <cylinder>
              <length>0.005</length>
              <radius>0.128</radius>
            </cylinder>
          </geometry>
          <surface>
            <contact>
              <ode/>
            </contact>
            <friction>
              <ode/>
              <torsional>
                <ode/>
              </torsional>
            </friction>
            <bounce/>
          </surface>
          <max_contacts>10</max_contacts>
        </collision>
        <visual name='rotor_1_visual'>
          <pose frame=''>0 0 0 0 -0 0</pose>
          <geometry>
            <mesh>
              <scale>0.6 0.6 0.6</scale>
              <uri>model://iris/meshes/iris_prop_ccw.dae</uri>
            </mesh>
          </geometry>
          <material>
            <script>
              <name>Gazebo/DarkGrey</name>
              <uri>file://media/materials/scripts/gazebo.material</uri>
            </script>
          </material>
        </visual>
        <gravity>1</gravity>
        <velocity_decay/>
        <self_collide>0</self_collide>
        <enable_wind>0</enable_wind>
        <kinematic>0</kinematic>
      </link>
      <joint name='rotor_1_joint' type='revolute'>
        <child>rotor_1</child>
        <parent>base_link</parent>
        <axis>
          <xyz>0 0 1</xyz>
          <limit>
            <lower>-1e+16</lower>
            <upper>1e+16</upper>
          </limit>
          <dynamics>
            <spring_reference>0</spring_reference>
            <spring_stiffness>0</spring_stiffness>
          </dynamics>
          <use_parent_model_frame>1</use_parent_model_frame>
        </axis>
      </joint>
      <link name='rotor_2'>
        <pose frame=''>0.0935 0.107 0.03 0 -0 0</pose>
        <inertial>
          <pose frame=''>0 0 0 0 -0 0</pose>
          <mass>0.005</mass>
          <inertia>
            <ixx>9.75e-07</ixx>
            <ixy>0</ixy>
            <ixz>0</ixz>
            <iyy>0.000273104</iyy>
            <iyz>0</iyz>
            <izz>0.000274004</izz>
          </inertia>
        </inertial>
        <collision name='rotor_2_collision'>
          <pose frame=''>0 0 0 0 -0 0</pose>
          <geometry>
            <cylinder>
              <length>0.005</length>
              <radius>0.128</radius>
            </cylinder>
          </geometry>
          <surface>
            <contact>
              <ode/>
            </contact>
            <friction>
              <ode/>
              <torsional>
                <ode/>
              </torsional>
            </friction>
            <bounce/>
          </surface>
          <max_contacts>10</max_contacts>
        </collision>
        <visual name='rotor_2_visual'>
          <pose frame=''>0 0 0 0 -0 0</pose>
          <geometry>
            <mesh>
              <scale>0.6 0.6 0.6</scale>
              <uri>model://iris/meshes/iris_prop_cw.dae</uri>
            </mesh>
          </geometry>
          <material>
            <script>
              <name>Gazebo/Blue</name>
              <uri>file://media/materials/scripts/gazebo.material</uri>
            </script>
          </material>
        </visual>
        <gravity>1</gravity>
        <velocity_decay/>
        <self_collide>0</self_collide>
        <enable_wind>0</enable_wind>
        <kinematic>0</kinematic>
      </link>
      <joint name='rotor_2_joint' type='revolute'>
        <child>rotor_2</child>
        <parent>base_link</parent>
        <axis>
          <xyz>0 0 1</xyz>
          <limit>
            <lower>-1e+16</lower>
            <upper>1e+16</upper>
          </limit>
          <dynamics>
            <spring_reference>0</spring_reference>
            <spring_stiffness>0</spring_stiffness>
          </dynamics>
          <use_parent_model_frame>1</use_parent_model_frame>
        </axis>
      </joint>
      <link name='rotor_3'>
        <pose frame=''>-0.0935 -0.107 0.03 0 -0 0</pose>
        <inertial>
          <pose frame=''>0 0 0 0 -0 0</pose>
          <mass>0.005</mass>
          <inertia>
            <ixx>9.75e-07</ixx>
            <ixy>0</ixy>
            <ixz>0</ixz>
            <iyy>0.000273104</iyy>
            <iyz>0</iyz>
            <izz>0.000274004</izz>
          </inertia>
        </inertial>
        <collision name='rotor_3_collision'>
          <pose frame=''>0 0 0 0 -0 0</pose>
          <geometry>
            <cylinder>
              <length>0.005</length>
              <radius>0.128</radius>
            </cylinder>
          </geometry>
          <surface>
            <contact>
              <ode/>
            </contact>
            <friction>
              <ode/>
              <torsional>
                <ode/>
              </torsional>
            </friction>
            <bounce/>
          </surface>
          <max_contacts>10</max_contacts>
        </collision>
        <visual name='rotor_3_visual'>
          <pose frame=''>0 0 0 0 -0 0</pose>
          <geometry>
            <mesh>
              <scale>0.6 0.6 0.6</scale>
              <uri>model://iris/meshes/iris_prop_cw.dae</uri>
            </mesh>
          </geometry>
          <material>
            <script>
              <name>Gazebo/DarkGrey</name>
              <uri>file://media/materials/scripts/gazebo.material</uri>
            </script>
          </material>
        </visual>
        <gravity>1</gravity>
        <velocity_decay/>
        <self_collide>0</self_collide>
        <enable_wind>0</enable_wind>
        <kinematic>0</kinematic>
      </link>
      <joint name='rotor_3_joint' type='revolute'>
        <child>rotor_3</child>
        <parent>base_link</parent>
        <axis>
          <xyz>0 0 1</xyz>
          <limit>
            <lower>-1e+16</lower>
            <upper>1e+16</upper>
          </limit>
          <dynamics>
            <spring_reference>0</spring_reference>
            <spring_stiffness>0</spring_stiffness>
          </dynamics>
          <use_parent_model_frame>1</use_parent_model_frame>
        </axis>
      </joint>
      <link name='gps::link'>
        <pose frame=''>0 0 0.12 0 -0 0</pose>
        <inertial>
          <pose frame=''>0 0 0 0 -0 0</pose>
          <mass>0.015</mass>
          <inertia>
            <ixx>1e-05</ixx>
            <ixy>0</ixy>
            <ixz>0</ixz>
            <iyy>1e-05</iyy>
            <iyz>0</iyz>
            <izz>1e-05</izz>
          </inertia>
        </inertial>
        <visual name='visual'>
          <geometry>
            <cylinder>
              <radius>0.01</radius>
              <length>0.002</length>
            </cylinder>
          </geometry>
          <material>
            <script>
              <name>Gazebo/Black</name>
              <uri>__default__</uri>
            </script>
          </material>
        </visual>
        <sensor name='gps' type='gps'>
          <pose frame=''>0 0 0 0 -0 0</pose>
          <update_rate>5</update_rate>
          <always_on>1</always_on>
          <visualize>0</visualize>
          <plugin name='gps_plugin' filename='libgazebo_gps_plugin.so'>
            <robotNamespace/>
            <gpsNoise>1</gpsNoise>
            <gpsXYRandomWalk>2.0</gpsXYRandomWalk>
            <gpsZRandomWalk>4.0</gpsZRandomWalk>
            <gpsXYNoiseDensity>2.0e-4</gpsXYNoiseDensity>
            <gpsZNoiseDensity>4.0e-4</gpsZNoiseDensity>
            <gpsVXYNoiseDensity>0.2</gpsVXYNoiseDensity>
            <gpsVZNoiseDensity>0.4</gpsVZNoiseDensity>
          </plugin>
          <gps/>
        </sensor>
        <self_collide>0</self_collide>
        <enable_wind>0</enable_wind>
        <kinematic>0</kinematic>
      </link>
      <joint name='gps_joint' type='fixed'>
        <child>gps::link</child>
        <parent>base_link</parent>
      </joint>
      <plugin name='rosbag' filename='libgazebo_multirotor_base_plugin.so'>
        <robotNamespace/>
        <linkName>base_link</linkName>
        <rotorVelocitySlowdownSim>10</rotorVelocitySlowdownSim>
      </plugin>
      <plugin name='front_right_motor_model' filename='libgazebo_motor_model.so'>
        <robotNamespace/>
        <jointName>rotor_0_joint</jointName>
        <linkName>rotor_0</linkName>
        <turningDirection>ccw</turningDirection>
        <timeConstantUp>0.0125</timeConstantUp>
        <timeConstantDown>0.025</timeConstantDown>
        <maxRotVelocity>1100</maxRotVelocity>
        <motorConstant>8.54858e-06</motorConstant>
        <momentConstant>0.06</momentConstant>
        <commandSubTopic>/gazebo/command/motor_speed</commandSubTopic>
        <motorNumber>0</motorNumber>
        <rotorDragCoefficient>0.000806428</rotorDragCoefficient>
        <rollingMomentCoefficient>1e-06</rollingMomentCoefficient>
        <motorSpeedPubTopic>/motor_speed/0</motorSpeedPubTopic>
        <rotorVelocitySlowdownSim>10</rotorVelocitySlowdownSim>
      </plugin>
      <plugin name='back_left_motor_model' filename='libgazebo_motor_model.so'>
        <robotNamespace/>
        <jointName>rotor_1_joint</jointName>
        <linkName>rotor_1</linkName>
        <turningDirection>ccw</turningDirection>
        <timeConstantUp>0.0125</timeConstantUp>
        <timeConstantDown>0.025</timeConstantDown>
        <maxRotVelocity>1100</maxRotVelocity>
        <motorConstant>8.54858e-06</motorConstant>
        <momentConstant>0.06</momentConstant>
        <commandSubTopic>/gazebo/command/motor_speed</commandSubTopic>
        <motorNumber>1</motorNumber>
        <rotorDragCoefficient>0.000806428</rotorDragCoefficient>
        <rollingMomentCoefficient>1e-06</rollingMomentCoefficient>
        <motorSpeedPubTopic>/motor_speed/1</motorSpeedPubTopic>
        <rotorVelocitySlowdownSim>10</rotorVelocitySlowdownSim>
      </plugin>
      <plugin name='front_left_motor_model' filename='libgazebo_motor_model.so'>
        <robotNamespace/>
        <jointName>rotor_2_joint</jointName>
        <linkName>rotor_2</linkName>
        <turningDirection>cw</turningDirection>
        <timeConstantUp>0.0125</timeConstantUp>
        <timeConstantDown>0.025</timeConstantDown>
        <maxRotVelocity>1100</maxRotVelocity>
        <motorConstant>8.54858e-06</motorConstant>
        <momentConstant>0.06</momentConstant>
        <commandSubTopic>/gazebo/command/motor_speed</commandSubTopic>
        <motorNumber>2</motorNumber>
        <rotorDragCoefficient>0.000806428</rotorDragCoefficient>
        <rollingMomentCoefficient>1e-06</rollingMomentCoefficient>
        <motorSpeedPubTopic>/motor_speed/2</motorSpeedPubTopic>
        <rotorVelocitySlowdownSim>10</rotorVelocitySlowdownSim>
      </plugin>
      <plugin name='back_right_motor_model' filename='libgazebo_motor_model.so'>
        <robotNamespace/>
        <jointName>rotor_3_joint</jointName>
        <linkName>rotor_3</linkName>
        <turningDirection>cw</turningDirection>
        <timeConstantUp>0.0125</timeConstantUp>
        <timeConstantDown>0.025</timeConstantDown>
        <maxRotVelocity>1100</maxRotVelocity>
        <motorConstant>8.54858e-06</motorConstant>
        <momentConstant>0.06</momentConstant>
        <commandSubTopic>/gazebo/command/motor_speed</commandSubTopic>
        <motorNumber>3</motorNumber>
        <rotorDragCoefficient>0.000806428</rotorDragCoefficient>
        <rollingMomentCoefficient>1e-06</rollingMomentCoefficient>
        <motorSpeedPubTopic>/motor_speed/3</motorSpeedPubTopic>
        <rotorVelocitySlowdownSim>10</rotorVelocitySlowdownSim>
      </plugin>
      <plugin name='groundtruth_plugin' filename='libgazebo_groundtruth_plugin.so'>
        <robotNamespace/>
      </plugin>
      <plugin name='magnetometer_plugin' filename='libgazebo_magnetometer_plugin.so'>
        <robotNamespace/>
        <pubRate>20</pubRate>
        <noiseDensity>0.0004</noiseDensity>
        <randomWalk>6.4e-06</randomWalk>
        <biasCorrelationTime>600</biasCorrelationTime>
        <magTopic>/mag</magTopic>
      </plugin>
      <plugin name='barometer_plugin' filename='libgazebo_barometer_plugin.so'>
        <robotNamespace/>
        <pubRate>10</pubRate>
        <baroTopic>/baro</baroTopic>
      </plugin>
      <plugin name='mavlink_interface' filename='libgazebo_mavlink_interface.so'>
        <robotNamespace/>
        <imuSubTopic>/imu</imuSubTopic>
        <gpsSubTopic>/gps</gpsSubTopic>
        <magSubTopic>/mag</magSubTopic>
        <baroSubTopic>/baro</baroSubTopic>
        <mavlink_addr>INADDR_ANY</mavlink_addr>
        <mavlink_udp_port>14560</mavlink_udp_port>
        <mavlink_tcp_port>4560</mavlink_tcp_port>
        <serialEnabled>0</serialEnabled>
        <serialDevice>/dev/ttyACM0</serialDevice>
        <baudRate>921600</baudRate>
        <qgc_addr>INADDR_ANY</qgc_addr>
        <qgc_udp_port>14550</qgc_udp_port>
        <sdk_addr>INADDR_ANY</sdk_addr>
        <sdk_udp_port>14540</sdk_udp_port>
        <hil_mode>0</hil_mode>
        <hil_state_level>0</hil_state_level>
        <send_vision_estimation>1</send_vision_estimation>
        <send_odometry>0</send_odometry>
        <enable_lockstep>1</enable_lockstep>
        <use_tcp>1</use_tcp>
        <motorSpeedCommandPubTopic>/gazebo/command/motor_speed</motorSpeedCommandPubTopic>
        <control_channels>
          <channel name='rotor1'>
            <input_index>0</input_index>
            <input_offset>0</input_offset>
            <input_scaling>1000</input_scaling>
            <zero_position_disarmed>0</zero_position_disarmed>
            <zero_position_armed>100</zero_position_armed>
            <joint_control_type>velocity</joint_control_type>
          </channel>
          <channel name='rotor2'>
            <input_index>1</input_index>
            <input_offset>0</input_offset>
            <input_scaling>1000</input_scaling>
            <zero_position_disarmed>0</zero_position_disarmed>
            <zero_position_armed>100</zero_position_armed>
            <joint_control_type>velocity</joint_control_type>
          </channel>
          <channel name='rotor3'>
            <input_index>2</input_index>
            <input_offset>0</input_offset>
            <input_scaling>1000</input_scaling>
            <zero_position_disarmed>0</zero_position_disarmed>
            <zero_position_armed>100</zero_position_armed>
            <joint_control_type>velocity</joint_control_type>
          </channel>
          <channel name='rotor4'>
            <input_index>3</input_index>
            <input_offset>0</input_offset>
            <input_scaling>1000</input_scaling>
            <zero_position_disarmed>0</zero_position_disarmed>
            <zero_position_armed>100</zero_position_armed>
            <joint_control_type>velocity</joint_control_type>
          </channel>
          <channel name='rotor5'>
            <input_index>4</input_index>
            <input_offset>1</input_offset>
            <input_scaling>324.6</input_scaling>
            <zero_position_disarmed>0</zero_position_disarmed>
            <zero_position_armed>0</zero_position_armed>
            <joint_control_type>velocity</joint_control_type>
            <joint_control_pid>
              <p>0.1</p>
              <i>0</i>
              <d>0</d>
              <iMax>0.0</iMax>
              <iMin>0.0</iMin>
              <cmdMax>2</cmdMax>
              <cmdMin>-2</cmdMin>
            </joint_control_pid>
            <joint_name>zephyr_delta_wing::propeller_joint</joint_name>
          </channel>
          <channel name='rotor6'>
            <input_index>5</input_index>
            <input_offset>0</input_offset>
            <input_scaling>0.524</input_scaling>
            <zero_position_disarmed>0</zero_position_disarmed>
            <zero_position_armed>0</zero_position_armed>
            <joint_control_type>position</joint_control_type>
            <joint_name>zephyr_delta_wing::flap_left_joint</joint_name>
            <joint_control_pid>
              <p>10.0</p>
              <i>0</i>
              <d>0</d>
              <iMax>0</iMax>
              <iMin>0</iMin>
              <cmdMax>20</cmdMax>
              <cmdMin>-20</cmdMin>
            </joint_control_pid>
          </channel>
          <channel name='rotor7'>
            <input_index>6</input_index>
            <input_offset>0</input_offset>
            <input_scaling>0.524</input_scaling>
            <zero_position_disarmed>0</zero_position_disarmed>
            <zero_position_armed>0</zero_position_armed>
            <joint_control_type>position</joint_control_type>
            <joint_name>zephyr_delta_wing::flap_right_joint</joint_name>
            <joint_control_pid>
              <p>10.0</p>
              <i>0</i>
              <d>0</d>
              <iMax>0</iMax>
              <iMin>0</iMin>
              <cmdMax>20</cmdMax>
              <cmdMin>-20</cmdMin>
            </joint_control_pid>
          </channel>
          <channel name='rotor8'>
            <input_index>7</input_index>
            <input_offset>0</input_offset>
            <input_scaling>0.524</input_scaling>
            <zero_position_disarmed>0</zero_position_disarmed>
            <zero_position_armed>0</zero_position_armed>
            <joint_control_type>position</joint_control_type>
          </channel>
        </control_channels>
      </plugin>
      <static>0</static>
      <plugin name='rotors_gazebo_imu_plugin' filename='libgazebo_imu_plugin.so'>
        <robotNamespace/>
        <linkName>/imu_link</linkName>
        <imuTopic>/imu</imuTopic>
        <gyroscopeNoiseDensity>0.00018665</gyroscopeNoiseDensity>
        <gyroscopeRandomWalk>3.8785e-05</gyroscopeRandomWalk>
        <gyroscopeBiasCorrelationTime>1000.0</gyroscopeBiasCorrelationTime>
        <gyroscopeTurnOnBiasSigma>0.0087</gyroscopeTurnOnBiasSigma>
        <accelerometerNoiseDensity>0.00186</accelerometerNoiseDensity>
        <accelerometerRandomWalk>0.006</accelerometerRandomWalk>
        <accelerometerBiasCorrelationTime>300.0</accelerometerBiasCorrelationTime>
        <accelerometerTurnOnBiasSigma>0.196</accelerometerTurnOnBiasSigma>
      </plugin>
      <link name='depthcamera_link'>
        <pose frame=''>0.08 0 -0.01 0 -0 0</pose>
        <inertial>
          <pose frame=''>0.01 0.025 0.025 0 -0 0</pose>
          <mass>0.01</mass>
          <inertia>
            <ixx>4.15e-06</ixx>
            <ixy>0</ixy>
            <ixz>0</ixz>
            <iyy>2.407e-06</iyy>
            <iyz>0</iyz>
            <izz>2.407e-06</izz>
          </inertia>
        </inertial>
        <sensor name='depth_camera' type='depth'>
          <update_rate>20</update_rate>
          <camera name='__default__'>
            <horizontal_fov>1.02974</horizontal_fov>
            <image>
              <format>R8G8B8</format>
              <width>64</width>
              <height>48</height>
            </image>
            <clip>
              <near>0.5</near>
              <far>18</far>
            </clip>
          </camera>
          <plugin name='camera_controller' filename='libgazebo_ros_openni_kinect.so'>
            <cameraName>camera</cameraName>
            <alwaysOn>1</alwaysOn>
            <updateRate>20</updateRate>
            <pointCloudCutoff>0.2</pointCloudCutoff>
            <pointCloudCutoffMax>20</pointCloudCutoffMax>
            <imageTopicName>rgb/image_raw</imageTopicName>
            <cameraInfoTopicName>rgb/camera_info</cameraInfoTopicName>
            <depthImageTopicName>depth/image_raw</depthImageTopicName>
            <depthImageCameraInfoTopicName>depth/camera_info</depthImageCameraInfoTopicName>
            <pointCloudTopicName>depth/points</pointCloudTopicName>
            <frameName>camera_link</frameName>
            <distortion_k1>0.0</distortion_k1>
            <distortion_k2>0.0</distortion_k2>
            <distortion_k3>0.0</distortion_k3>
            <distortion_t1>0.0</distortion_t1>
            <distortion_t2>0.0</distortion_t2>
          </plugin>
        </sensor>
        <self_collide>0</self_collide>
        <enable_wind>0</enable_wind>
        <kinematic>0</kinematic>
      </link>
      <joint name='depth_camera_joint' type='revolute'>
        <child>depthcamera_link</child>
        <parent>base_link</parent>
        <axis>
          <xyz>0 0 1</xyz>
          <limit>
            <upper>0</upper>
            <lower>0</lower>
          </limit>
          <use_parent_model_frame>0</use_parent_model_frame>
          <dynamics>
            <spring_reference>0</spring_reference>
            <spring_stiffness>0</spring_stiffness>
          </dynamics>
        </axis>
      </joint>
      <pose frame=''>0.26528 -0.4778 0 0 -0 0</pose>
    </model>
    <state world_name='default'>
      <sim_time>73 87000000</sim_time>
      <real_time>78 822953611</real_time>
      <wall_time>1613682335 64395114</wall_time>
      <iterations>73087</iterations>
      <model name='ground_plane'>
        <pose frame=''>0 0 0 0 -0 0</pose>
        <scale>1 1 1</scale>
        <link name='link'>
          <pose frame=''>0 0 0 0 -0 0</pose>
          <velocity>0 0 0 0 -0 0</velocity>
          <acceleration>0 0 0 0 -0 0</acceleration>
          <wrench>0 0 0 0 -0 0</wrench>
        </link>
      </model>
      <model name='px4vision'>
        <pose frame=''>0.26528 -0.4778 0.054 0 -0 0</pose>
        <scale>1 1 1</scale>
        <link name='/imu_link'>
          <pose frame=''>0.26528 -0.4778 0.054 0 -0 0</pose>
          <velocity>0 0 -0 0 -0 0</velocity>
          <acceleration>1.5e-05 1.5e-05 0 -3.3e-05 3.6e-05 -9e-06</acceleration>
          <wrench>0 0 0 0 -0 0</wrench>
        </link>
        <link name='base_link'>
          <pose frame=''>0.26528 -0.4778 0.054 0 -0 0</pose>
          <velocity>0 0 -0 0 -0 0</velocity>
          <acceleration>1e-06 1e-06 0 -2e-05 2e-05 0</acceleration>
          <wrench>2e-06 2e-06 0 0 -0 0</wrench>
        </link>
        <link name='depthcamera_link'>
          <pose frame=''>0.34528 -0.4778 0.044 0 -0 0</pose>
          <velocity>0 0 -0 0 -0 0</velocity>
          <acceleration>1.3e-05 8e-06 -2e-06 1.4e-05 -3e-05 1.1e-05</acceleration>
          <wrench>0 0 -0 0 -0 0</wrench>
        </link>
        <link name='gps::link'>
          <pose frame=''>0.26528 -0.4778 0.174 0 -0 0</pose>
          <velocity>3e-06 3e-06 -0 1.3e-05 -1.3e-05 0</velocity>
          <acceleration>0.006875 0.006923 0 0.025376 -0.025201 -9e-06</acceleration>
          <wrench>0.000103 0.000104 0 0 -0 0</wrench>
        </link>
        <link name='rotor_0'>
          <pose frame=''>0.35878 -0.5848 0.084 0 -0 0</pose>
          <velocity>0 0 -0 0 -0 0</velocity>
          <acceleration>9e-06 9e-06 0 -2.8e-05 2.8e-05 0</acceleration>
          <wrench>0 0 0 0 -0 0</wrench>
        </link>
        <link name='rotor_1'>
          <pose frame=''>0.17178 -0.3708 0.084 0 -0 0</pose>
          <velocity>0 0 -0 0 -0 0</velocity>
          <acceleration>9e-06 1e-05 -0 -2.8e-05 2.8e-05 0</acceleration>
          <wrench>0 0 -0 0 -0 0</wrench>
        </link>
        <link name='rotor_2'>
          <pose frame=''>0.35878 -0.3708 0.084 0 -0 0</pose>
          <velocity>0 0 -0 0 -0 0</velocity>
          <acceleration>9e-06 9e-06 -6e-06 -2.8e-05 2.8e-05 0</acceleration>
          <wrench>0 0 -0 0 -0 0</wrench>
        </link>
        <link name='rotor_3'>
          <pose frame=''>0.17178 -0.5848 0.084 0 -0 0</pose>
          <velocity>0 0 -0 0 -0 0</velocity>
          <acceleration>9e-06 1e-05 6e-06 -2.8e-05 2.8e-05 0</acceleration>
          <wrench>0 0 0 0 -0 0</wrench>
        </link>
      </model>
      <light name='sun'>
        <pose frame=''>0 0 10 0 -0 0</pose>
      </light>
    </state>
    <gui fullscreen='0'>
      <camera name='user_camera'>
        <pose frame=''>5 -5 2 0 0.275643 2.35619</pose>
        <view_controller>orbit</view_controller>
        <projection_type>perspective</projection_type>
      </camera>
    </gui>
  </world>
</sdf>
