<?xml version="1.0" ?>
<sdf version='1.6'>
  <world name='default'>
    <light name='sun' type='directional'>
      <cast_shadows>1</cast_shadows>
      <pose frame=''>0 0 10 0 -0 0</pose>
      <diffuse>0.8 0.8 0.8 1</diffuse>
      <specular>0.2 0.2 0.2 1</specular>
      <attenuation>
        <range>1000</range>
        <constant>0.9</constant>
        <linear>0.01</linear>
        <quadratic>0.001</quadratic>
      </attenuation>
      <direction>-0.5 0.1 -0.9</direction>
    </light>
    <model name='ground_plane'>
      <static>1</static>
      <link name='link'>
        <collision name='collision'>
          <geometry>
            <plane>
              <normal>0 0 1</normal>
              <size>100 100</size>
            </plane>
          </geometry>
          <surface>
            <contact>
              <collide_bitmask>65535</collide_bitmask>
              <ode/>
            </contact>
            <friction>
              <ode>
                <mu>100</mu>
                <mu2>50</mu2>
              </ode>
              <torsional>
                <ode/>
              </torsional>
            </friction>
            <bounce/>
          </surface>
          <max_contacts>10</max_contacts>
        </collision>
        <visual name='visual'>
          <cast_shadows>0</cast_shadows>
          <geometry>
            <plane>
              <normal>0 0 1</normal>
              <size>100 100</size>
            </plane>
          </geometry>
          <material>
            <script>
              <uri>file://media/materials/scripts/gazebo.material</uri>
              <name>Gazebo/Grey</name>
            </script>
          </material>
        </visual>
        <self_collide>0</self_collide>
        <enable_wind>1</enable_wind>
        <kinematic>0</kinematic>
      </link>
    </model>
    <model name='typhoon_h480'>
      <pose frame=''>0 0 0.26 0 -0 -3.14159</pose>
      <link name='base_link'>
        <pose frame=''>0 0 0 0 -0 0</pose>
        <inertial>
          <pose frame=''>0.001005 0 -0.009004 0 -0 0</pose>
          <mass>2.02</mass>
          <inertia>
            <ixx>0.011</ixx>
            <ixy>0</ixy>
            <ixz>0</ixz>
            <iyy>0.015</iyy>
            <iyz>0</iyz>
            <izz>0.021</izz>
          </inertia>
        </inertial>
        <collision name='base_link_collision'>
          <pose frame=''>0 0 0 0 -0 0</pose>
          <geometry>
            <box>
              <size>0.67 0.67 0.15</size>
            </box>
          </geometry>
          <surface>
            <contact>
              <ode>
                <min_depth>0.001</min_depth>
                <max_vel>0</max_vel>
              </ode>
            </contact>
            <friction>
              <ode/>
              <torsional>
                <ode/>
              </torsional>
            </friction>
            <bounce/>
          </surface>
          <max_contacts>10</max_contacts>
        </collision>
        <visual name='base_link_visual'>
          <pose frame=''>0 0 0 0 -0 0</pose>
          <geometry>
            <mesh>
              <scale>0.001 0.001 0.001</scale>
              <uri>model://typhoon_h480/meshes/main_body_remeshed_v3.stl</uri>
            </mesh>
          </geometry>
          <material>
            <script>
              <name>Gazebo/DarkGrey</name>
              <uri>file://media/materials/scripts/gazebo.material</uri>
            </script>
          </material>
        </visual>
        <gravity>1</gravity>
        <velocity_decay/>
        <self_collide>0</self_collide>
        <enable_wind>1</enable_wind>
        <kinematic>0</kinematic>
      </link>
      <link name='cgo3_mount_link'>
        <inertial>
          <pose frame=''>-0.041 0 -0.162 0 -0 0</pose>
          <mass>0.1</mass>
          <inertia>
            <ixx>0.001</ixx>
            <ixy>0</ixy>
            <ixz>0</ixz>
            <iyy>0.001</iyy>
            <iyz>0</iyz>
            <izz>0.001</izz>
          </inertia>
        </inertial>
        <visual name='cgo3_mount_visual'>
          <pose frame=''>0 0 0 0 -0 0</pose>
          <geometry>
            <mesh>
              <scale>0.001 0.001 0.001</scale>
              <uri>model://typhoon_h480/meshes/cgo3_mount_remeshed_v1.stl</uri>
            </mesh>
          </geometry>
          <material>
            <script>
              <name>Gazebo/DarkGrey</name>
              <uri>file://media/materials/scripts/gazebo.material</uri>
            </script>
          </material>
        </visual>
        <self_collide>0</self_collide>
        <enable_wind>1</enable_wind>
        <kinematic>0</kinematic>
      </link>
      <joint name='cgo3_mount_joint' type='revolute'>
        <child>cgo3_mount_link</child>
        <parent>base_link</parent>
        <pose frame=''>0 0 0 0 -0 0</pose>
        <axis>
          <xyz>0 0 1</xyz>
          <limit>
            <lower>0</lower>
            <upper>0</upper>
            <effort>100</effort>
            <velocity>-1</velocity>
          </limit>
          <dynamics>
            <damping>1</damping>
            <spring_reference>0</spring_reference>
            <spring_stiffness>0</spring_stiffness>
          </dynamics>
          <use_parent_model_frame>1</use_parent_model_frame>
        </axis>
        <physics>
          <ode>
            <implicit_spring_damper>1</implicit_spring_damper>
            <limit>
              <cfm>0</cfm>
              <erp>0.2</erp>
            </limit>
          </ode>
        </physics>
      </joint>
      <link name='cgo3_vertical_arm_link'>
        <inertial>
          <pose frame=''>-0.041 0 -0.162 0 -0 0</pose>
          <mass>0.1</mass>
          <inertia>
            <ixx>0.001</ixx>
            <ixy>0</ixy>
            <ixz>0</ixz>
            <iyy>0.001</iyy>
            <iyz>0</iyz>
            <izz>0.001</izz>
          </inertia>
        </inertial>
        <visual name='cgo3_vertical_arm_visual'>
          <pose frame=''>0 0 0 0 -0 0</pose>
          <geometry>
            <mesh>
              <scale>0.001 0.001 0.001</scale>
              <uri>model://typhoon_h480/meshes/cgo3_vertical_arm_remeshed_v1.stl</uri>
            </mesh>
          </geometry>
          <material>
            <script>
              <name>Gazebo/DarkGrey</name>
              <uri>file://media/materials/scripts/gazebo.material</uri>
            </script>
          </material>
        </visual>
        <self_collide>0</self_collide>
        <enable_wind>1</enable_wind>
        <kinematic>0</kinematic>
      </link>
      <joint name='cgo3_vertical_arm_joint' type='revolute'>
        <child>cgo3_vertical_arm_link</child>
        <parent>cgo3_mount_link</parent>
        <pose frame=''>-0.026 0 -0.1 0 -0 0</pose>
        <axis>
          <xyz>0 0 1</xyz>
          <limit>
            <lower>-1e+16</lower>
            <upper>1e+16</upper>
            <effort>100</effort>
            <velocity>-1</velocity>
          </limit>
          <dynamics>
            <damping>0.1</damping>
            <spring_reference>0</spring_reference>
            <spring_stiffness>0</spring_stiffness>
          </dynamics>
          <use_parent_model_frame>1</use_parent_model_frame>
        </axis>
        <physics>
          <ode>
            <implicit_spring_damper>1</implicit_spring_damper>
            <limit>
              <cfm>0.1</cfm>
              <erp>0.2</erp>
            </limit>
          </ode>
        </physics>
      </joint>
      <link name='cgo3_horizontal_arm_link'>
        <inertial>
          <pose frame=''>-0.041 0 -0.081 0 -0 0</pose>
          <mass>0.1</mass>
          <inertia>
            <ixx>0.001</ixx>
            <ixy>0</ixy>
            <ixz>0</ixz>
            <iyy>0.001</iyy>
            <iyz>0</iyz>
            <izz>0.001</izz>
          </inertia>
        </inertial>
        <visual name='cgo3_horizontal_arm_visual'>
          <pose frame=''>0 0 0 0 -0 0</pose>
          <geometry>
            <mesh>
              <scale>0.001 0.001 0.001</scale>
              <uri>model://typhoon_h480/meshes/cgo3_horizontal_arm_remeshed_v1.stl</uri>
            </mesh>
          </geometry>
          <material>
            <script>
              <name>Gazebo/DarkGrey</name>
              <uri>file://media/materials/scripts/gazebo.material</uri>
            </script>
          </material>
        </visual>
        <self_collide>0</self_collide>
        <enable_wind>1</enable_wind>
        <kinematic>0</kinematic>
      </link>
      <joint name='cgo3_horizontal_arm_joint' type='revolute'>
        <child>cgo3_horizontal_arm_link</child>
        <parent>cgo3_vertical_arm_link</parent>
        <pose frame=''>0.026 0 -0.162 0 -0 0</pose>
        <axis>
          <xyz>-1 0 0</xyz>
          <limit>
            <lower>-0.785398</lower>
            <upper>0.785398</upper>
            <effort>100</effort>
            <velocity>-1</velocity>
          </limit>
          <dynamics>
            <damping>0.1</damping>
            <spring_reference>0</spring_reference>
            <spring_stiffness>0</spring_stiffness>
          </dynamics>
          <use_parent_model_frame>1</use_parent_model_frame>
        </axis>
        <physics>
          <ode>
            <implicit_spring_damper>1</implicit_spring_damper>
            <limit>
              <cfm>0.1</cfm>
              <erp>0.2</erp>
            </limit>
          </ode>
        </physics>
      </joint>
      <link name='cgo3_camera_link'>
        <inertial>
          <pose frame=''>-0.041 0 -0.162 0 -0 0</pose>
          <mass>0.1</mass>
          <inertia>
            <ixx>0.001</ixx>
            <ixy>0</ixy>
            <ixz>0</ixz>
            <iyy>0.001</iyy>
            <iyz>0</iyz>
            <izz>0.001</izz>
          </inertia>
        </inertial>
        <collision name='cgo3_camera_collision'>
          <pose frame=''>-0.041 0 -0.162 0 -0 0</pose>
          <geometry>
            <sphere>
              <radius>0.035</radius>
            </sphere>
          </geometry>
          <surface>
            <friction>
              <ode>
                <mu>1</mu>
                <mu2>1</mu2>
              </ode>
              <torsional>
                <ode/>
              </torsional>
            </friction>
            <contact>
              <ode>
                <kp>1e+08</kp>
                <kd>1</kd>
                <max_vel>0.01</max_vel>
                <min_depth>0.001</min_depth>
              </ode>
            </contact>
            <bounce/>
          </surface>
          <max_contacts>10</max_contacts>
        </collision>
        <visual name='cgo3_camera_visual'>
          <pose frame=''>0 0 0 0 -0 0</pose>
          <geometry>
            <mesh>
              <scale>0.001 0.001 0.001</scale>
              <uri>model://typhoon_h480/meshes/cgo3_camera_remeshed_v1.stl</uri>
            </mesh>
          </geometry>
          <material>
            <script>
              <name>Gazebo/DarkGrey</name>
              <uri>file://media/materials/scripts/gazebo.material</uri>
            </script>
          </material>
        </visual>
        <sensor name='camera_imu' type='imu'>
          <always_on>1</always_on>
          <imu/>
        </sensor>
        <sensor name='camera' type='camera'>
          <pose frame=''>-0.051 0 -0.162 0 -0 3.14159</pose>
          <camera name='__default__'>
            <horizontal_fov>2</horizontal_fov>
            <image>
              <format>R8G8B8</format>
              <width>640</width>
              <height>360</height>
            </image>
            <clip>
              <near>0.05</near>
              <far>15000</far>
            </clip>
          </camera>
          <always_on>1</always_on>
          <update_rate>10</update_rate>
          <visualize>0</visualize>
          <plugin name='GstCameraPlugin' filename='libgazebo_gst_camera_plugin.so'>
            <robotNamespace/>
            <udpPort>5600</udpPort>
          </plugin>
          <plugin name='GeotaggedImagesPlugin' filename='libgazebo_geotagged_images_plugin.so'>
            <robotNamespace/>
            <interval>1</interval>
            <width>3840</width>
            <height>2160</height>
          </plugin>
        </sensor>
        <self_collide>0</self_collide>
        <enable_wind>1</enable_wind>
        <kinematic>0</kinematic>
      </link>
      <joint name='cgo3_camera_joint' type='revolute'>
        <child>cgo3_camera_link</child>
        <parent>cgo3_horizontal_arm_link</parent>
        <pose frame=''>-0.041 0.03 -0.162 0 -0 0</pose>
        <axis>
          <xyz>0 -1 0</xyz>
          <limit>
            <lower>-0.0872665</lower>
            <upper>1.5708</upper>
            <effort>100</effort>
            <velocity>-1</velocity>
          </limit>
          <dynamics>
            <damping>0.1</damping>
            <spring_reference>0</spring_reference>
            <spring_stiffness>0</spring_stiffness>
          </dynamics>
          <use_parent_model_frame>1</use_parent_model_frame>
        </axis>
        <physics>
          <ode>
            <implicit_spring_damper>1</implicit_spring_damper>
            <limit>
              <cfm>0.1</cfm>
              <erp>0.2</erp>
            </limit>
          </ode>
        </physics>
      </joint>
      <link name='left_leg'>
        <inertial>
          <pose frame=''>0 -0.14314 -0.207252 0 -0 0</pose>
          <mass>0.1</mass>
          <inertia>
            <ixx>0.001</ixx>
            <ixy>0</ixy>
            <ixz>0</ixz>
            <iyy>0.001</iyy>
            <iyz>0</iyz>
            <izz>0.001</izz>
          </inertia>
        </inertial>
        <collision name='collision'>
          <pose frame=''>-0.005 -0.14314 -0.207252 0 1.56893 0</pose>
          <geometry>
            <cylinder>
              <radius>0.012209</radius>
              <length>0.3</length>
            </cylinder>
          </geometry>
          <surface>
            <friction>
              <ode>
                <mu>1</mu>
                <mu2>1</mu2>
              </ode>
              <torsional>
                <ode/>
              </torsional>
            </friction>
            <contact>
              <ode>
                <kp>1e+08</kp>
                <kd>1</kd>
                <max_vel>0.01</max_vel>
                <min_depth>0.001</min_depth>
              </ode>
            </contact>
            <bounce/>
          </surface>
          <max_contacts>10</max_contacts>
        </collision>
        <collision name='collision_bar'>
          <pose frame=''>0.00052 -0.08503 -0.121187 -0.501318 0 0</pose>
          <geometry>
            <cylinder>
              <radius>0.00914984</radius>
              <length>0.176893</length>
            </cylinder>
          </geometry>
          <surface>
            <friction>
              <ode>
                <mu>1</mu>
                <mu2>1</mu2>
              </ode>
              <torsional>
                <ode/>
              </torsional>
            </friction>
            <contact>
              <ode>
                <kp>1e+08</kp>
                <kd>1</kd>
                <max_vel>0.01</max_vel>
                <min_depth>0.001</min_depth>
              </ode>
            </contact>
            <bounce/>
          </surface>
          <max_contacts>10</max_contacts>
        </collision>
        <visual name='base_link_left_leg'>
          <pose frame=''>0 0 0 0 -0 0</pose>
          <geometry>
            <mesh>
              <scale>0.001 0.001 0.001</scale>
              <uri>model://typhoon_h480/meshes/leg2_remeshed_v3.stl</uri>
            </mesh>
          </geometry>
          <material>
            <script>
              <name>Gazebo/DarkGrey</name>
              <uri>file://media/materials/scripts/gazebo.material</uri>
            </script>
          </material>
        </visual>
        <self_collide>0</self_collide>
        <enable_wind>1</enable_wind>
        <kinematic>0</kinematic>
      </link>
      <joint name='left_leg_joint' type='revolute'>
        <child>left_leg</child>
        <parent>base_link</parent>
        <pose frame=''>0.00026 -0.040515 -0.048 0 -0 0</pose>
        <axis>
          <xyz>-1 0 0</xyz>
          <limit>
            <lower>0</lower>
            <upper>1</upper>
            <effort>100</effort>
            <velocity>-1</velocity>
            <stiffness>1e+08</stiffness>
            <dissipation>1</dissipation>
          </limit>
          <dynamics>
            <damping>0.1</damping>
            <spring_reference>0</spring_reference>
            <spring_stiffness>0</spring_stiffness>
          </dynamics>
          <use_parent_model_frame>1</use_parent_model_frame>
        </axis>
        <physics>
          <ode>
            <implicit_spring_damper>1</implicit_spring_damper>
            <limit>
              <cfm>0</cfm>
              <erp>0.2</erp>
            </limit>
          </ode>
        </physics>
      </joint>
      <link name='right_leg'>
        <pose frame=''>0 0 0 0 -0 0</pose>
        <inertial>
          <pose frame=''>0 0.14314 -0.207252 0 -0 0</pose>
          <mass>0.1</mass>
          <inertia>
            <ixx>0.001</ixx>
            <ixy>0</ixy>
            <ixz>0</ixz>
            <iyy>0.001</iyy>
            <iyz>0</iyz>
            <izz>0.001</izz>
          </inertia>
        </inertial>
        <collision name='collision'>
          <pose frame=''>-0.005 0.14314 -0.207252 0 1.56893 0</pose>
          <geometry>
            <cylinder>
              <radius>0.012209</radius>
              <length>0.3</length>
            </cylinder>
          </geometry>
          <surface>
            <friction>
              <ode>
                <mu>1</mu>
                <mu2>1</mu2>
              </ode>
              <torsional>
                <ode/>
              </torsional>
            </friction>
            <contact>
              <ode>
                <kp>1e+08</kp>
                <kd>1</kd>
                <max_vel>0.01</max_vel>
                <min_depth>0.001</min_depth>
              </ode>
            </contact>
            <bounce/>
          </surface>
          <max_contacts>10</max_contacts>
        </collision>
        <collision name='collision_bar'>
          <pose frame=''>0.00052 0.08503 -0.121187 0.501318 -0 0</pose>
          <geometry>
            <cylinder>
              <radius>0.00914984</radius>
              <length>0.176893</length>
            </cylinder>
          </geometry>
          <surface>
            <friction>
              <ode>
                <mu>1</mu>
                <mu2>1</mu2>
              </ode>
              <torsional>
                <ode/>
              </torsional>
            </friction>
            <contact>
              <ode>
                <kp>1e+08</kp>
                <kd>1</kd>
                <max_vel>0.01</max_vel>
                <min_depth>0.001</min_depth>
              </ode>
            </contact>
            <bounce/>
          </surface>
          <max_contacts>10</max_contacts>
        </collision>
        <visual name='base_link_right_leg'>
          <pose frame=''>0 0 0 0 -0 0</pose>
          <geometry>
            <mesh>
              <scale>0.001 0.001 0.001</scale>
              <uri>model://typhoon_h480/meshes/leg1_remeshed_v3.stl</uri>
            </mesh>
          </geometry>
          <material>
            <script>
              <name>Gazebo/DarkGrey</name>
              <uri>file://media/materials/scripts/gazebo.material</uri>
            </script>
          </material>
        </visual>
        <self_collide>0</self_collide>
        <enable_wind>1</enable_wind>
        <kinematic>0</kinematic>
      </link>
      <joint name='right_leg_joint' type='revolute'>
        <child>right_leg</child>
        <parent>base_link</parent>
        <pose frame=''>0.00026 0.040515 -0.048 0 -0 0</pose>
        <axis>
          <xyz>1 0 0</xyz>
          <limit>
            <lower>0</lower>
            <upper>1</upper>
            <effort>100</effort>
            <velocity>-1</velocity>
            <stiffness>1e+08</stiffness>
            <dissipation>1</dissipation>
          </limit>
          <dynamics>
            <damping>0.1</damping>
            <spring_reference>0</spring_reference>
            <spring_stiffness>0</spring_stiffness>
          </dynamics>
          <use_parent_model_frame>1</use_parent_model_frame>
        </axis>
        <physics>
          <ode>
            <implicit_spring_damper>1</implicit_spring_damper>
            <limit>
              <cfm>0</cfm>
              <erp>0.2</erp>
            </limit>
          </ode>
        </physics>
      </joint>
      <link name='typhoon_h480/imu_link'>
        <pose frame=''>0 0 0 0 -0 -3.14159</pose>
        <inertial>
          <pose frame=''>0 0 0 0 -0 0</pose>
          <mass>0.015</mass>
          <inertia>
            <ixx>1e-05</ixx>
            <ixy>0</ixy>
            <ixz>0</ixz>
            <iyy>1e-05</iyy>
            <iyz>0</iyz>
            <izz>1e-05</izz>
          </inertia>
        </inertial>
        <self_collide>0</self_collide>
        <enable_wind>1</enable_wind>
        <kinematic>0</kinematic>
      </link>
      <joint name='typhoon_h480/imu_joint' type='revolute'>
        <child>typhoon_h480/imu_link</child>
        <parent>base_link</parent>
        <axis>
          <xyz>1 0 0</xyz>
          <limit>
            <lower>0</lower>
            <upper>0</upper>
            <effort>0</effort>
            <velocity>0</velocity>
          </limit>
          <dynamics>
            <spring_reference>0</spring_reference>
            <spring_stiffness>0</spring_stiffness>
          </dynamics>
          <use_parent_model_frame>1</use_parent_model_frame>
        </axis>
      </joint>
      <link name='rotor_3'>
        <pose frame=''>0.211396 0.119762 0.082219 0 -0 0</pose>
        <inertial>
          <pose frame=''>0 0 0 0 -0 0</pose>
          <mass>0.005</mass>
          <inertia>
            <ixx>9.75e-07</ixx>
            <ixy>0</ixy>
            <ixz>0</ixz>
            <iyy>0.000273104</iyy>
            <iyz>0</iyz>
            <izz>0.000274004</izz>
          </inertia>
        </inertial>
        <collision name='rotor_3_collision'>
          <pose frame=''>0 0 0 0 -0 0</pose>
          <geometry>
            <cylinder>
              <length>0.005</length>
              <radius>0.128</radius>
            </cylinder>
          </geometry>
          <surface>
            <contact>
              <ode/>
            </contact>
            <friction>
              <ode/>
              <torsional>
                <ode/>
              </torsional>
            </friction>
            <bounce/>
          </surface>
          <max_contacts>10</max_contacts>
        </collision>
        <visual name='rotor_3_visual'>
          <pose frame=''>-0.211396 -0.119762 -0.082219 0 -0 0</pose>
          <geometry>
            <mesh>
              <scale>0.001 0.001 0.001</scale>
              <uri>model://typhoon_h480/meshes/prop_ccw_assembly_remeshed_v3.stl</uri>
            </mesh>
          </geometry>
          <material>
            <script>
              <name>Gazebo/Blue</name>
              <uri>file://media/materials/scripts/gazebo.material</uri>
            </script>
          </material>
        </visual>
        <gravity>1</gravity>
        <velocity_decay/>
        <self_collide>0</self_collide>
        <enable_wind>1</enable_wind>
        <kinematic>0</kinematic>
      </link>
      <joint name='rotor_3_joint' type='revolute'>
        <child>rotor_3</child>
        <parent>base_link</parent>
        <axis>
          <xyz>0.0446 -0.0825 1.8977</xyz>
          <limit>
            <lower>-1e+16</lower>
            <upper>1e+16</upper>
            <effort>10</effort>
            <velocity>-1</velocity>
          </limit>
          <dynamics>
            <damping>0.005</damping>
            <spring_reference>0</spring_reference>
            <spring_stiffness>0</spring_stiffness>
          </dynamics>
          <use_parent_model_frame>1</use_parent_model_frame>
        </axis>
        <physics>
          <ode>
            <implicit_spring_damper>1</implicit_spring_damper>
            <limit>
              <cfm>0</cfm>
              <erp>0.2</erp>
            </limit>
          </ode>
        </physics>
      </joint>
      <link name='rotor_0'>
        <pose frame=''>-0.209396 0.122762 0.082219 0 -0 2.0944</pose>
        <inertial>
          <pose frame=''>0 0 0 0 -0 0</pose>
          <mass>0.005</mass>
          <inertia>
            <ixx>9.75e-07</ixx>
            <ixy>0</ixy>
            <ixz>0</ixz>
            <iyy>0.000273104</iyy>
            <iyz>0</iyz>
            <izz>0.000274004</izz>
          </inertia>
        </inertial>
        <collision name='rotor_0_collision'>
          <pose frame=''>0 0 0 0 -0 0</pose>
          <geometry>
            <cylinder>
              <length>0.005</length>
              <radius>0.128</radius>
            </cylinder>
          </geometry>
          <surface>
            <contact>
              <ode/>
            </contact>
            <friction>
              <ode/>
              <torsional>
                <ode/>
              </torsional>
            </friction>
            <bounce/>
          </surface>
          <max_contacts>10</max_contacts>
        </collision>
        <visual name='rotor_0_visual'>
          <pose frame=''>-0.211396 -0.119762 -0.082219 0 -0 0</pose>
          <geometry>
            <mesh>
              <scale>0.001 0.001 0.001</scale>
              <uri>model://typhoon_h480/meshes/prop_ccw_assembly_remeshed_v3.stl</uri>
            </mesh>
          </geometry>
          <material>
            <script>
              <name>Gazebo/Blue</name>
              <uri>file://media/materials/scripts/gazebo.material</uri>
            </script>
          </material>
        </visual>
        <gravity>1</gravity>
        <velocity_decay/>
        <self_collide>0</self_collide>
        <enable_wind>1</enable_wind>
        <kinematic>0</kinematic>
      </link>
      <joint name='rotor_0_joint' type='revolute'>
        <child>rotor_0</child>
        <parent>base_link</parent>
        <axis>
          <xyz>0.046 0.0827 1.8977</xyz>
          <limit>
            <lower>-1e+16</lower>
            <upper>1e+16</upper>
            <effort>10</effort>
            <velocity>-1</velocity>
          </limit>
          <dynamics>
            <damping>0.005</damping>
            <spring_reference>0</spring_reference>
            <spring_stiffness>0</spring_stiffness>
          </dynamics>
          <use_parent_model_frame>1</use_parent_model_frame>
        </axis>
        <physics>
          <ode>
            <implicit_spring_damper>1</implicit_spring_damper>
            <limit>
              <cfm>0</cfm>
              <erp>0.2</erp>
            </limit>
          </ode>
        </physics>
      </joint>
      <link name='rotor_4'>
        <pose frame=''>-0.001879 0.242705 0.082217 0 -0 0</pose>
        <inertial>
          <pose frame=''>0 0 0 0 -0 0</pose>
          <mass>0.005</mass>
          <inertia>
            <ixx>9.75e-07</ixx>
            <ixy>0</ixy>
            <ixz>0</ixz>
            <iyy>0.000273104</iyy>
            <iyz>0</iyz>
            <izz>0.000274004</izz>
          </inertia>
        </inertial>
        <collision name='rotor_4_collision'>
          <pose frame=''>0 0 0 0 -0 0</pose>
          <geometry>
            <cylinder>
              <length>0.005</length>
              <radius>0.128</radius>
            </cylinder>
          </geometry>
          <surface>
            <contact>
              <ode/>
            </contact>
            <friction>
              <ode/>
              <torsional>
                <ode/>
              </torsional>
            </friction>
            <bounce/>
          </surface>
          <max_contacts>10</max_contacts>
        </collision>
        <visual name='rotor_4_visual'>
          <pose frame=''>0.001879 -0.242705 -0.082217 0 -0 0</pose>
          <geometry>
            <mesh>
              <scale>0.001 0.001 0.001</scale>
              <uri>model://typhoon_h480/meshes/prop_cw_assembly_remeshed_v3.stl</uri>
            </mesh>
          </geometry>
          <material>
            <script>
              <name>Gazebo/DarkGrey</name>
              <uri>file://media/materials/scripts/gazebo.material</uri>
            </script>
          </material>
        </visual>
        <gravity>1</gravity>
        <velocity_decay/>
        <self_collide>0</self_collide>
        <enable_wind>1</enable_wind>
        <kinematic>0</kinematic>
      </link>
      <joint name='rotor_4_joint' type='revolute'>
        <child>rotor_4</child>
        <parent>base_link</parent>
        <axis>
          <xyz>-0.09563 -0.0003 1.8976</xyz>
          <limit>
            <lower>-1e+16</lower>
            <upper>1e+16</upper>
            <effort>10</effort>
            <velocity>-1</velocity>
          </limit>
          <dynamics>
            <damping>0.005</damping>
            <spring_reference>0</spring_reference>
            <spring_stiffness>0</spring_stiffness>
          </dynamics>
          <use_parent_model_frame>1</use_parent_model_frame>
        </axis>
        <physics>
          <ode>
            <implicit_spring_damper>1</implicit_spring_damper>
            <limit>
              <cfm>0</cfm>
              <erp>0.2</erp>
            </limit>
          </ode>
        </physics>
      </joint>
      <link name='rotor_1'>
        <pose frame=''>0.211396 -0.119762 0.082219 0 0 -2.0944</pose>
        <inertial>
          <pose frame=''>0 0 0 0 -0 0</pose>
          <mass>0.005</mass>
          <inertia>
            <ixx>9.75e-07</ixx>
            <ixy>0</ixy>
            <ixz>0</ixz>
            <iyy>0.000273104</iyy>
            <iyz>0</iyz>
            <izz>0.000274004</izz>
          </inertia>
        </inertial>
        <collision name='rotor_1_collision'>
          <pose frame=''>0 0 0 0 -0 0</pose>
          <geometry>
            <cylinder>
              <length>0.005</length>
              <radius>0.128</radius>
            </cylinder>
          </geometry>
          <surface>
            <contact>
              <ode/>
            </contact>
            <friction>
              <ode/>
              <torsional>
                <ode/>
              </torsional>
            </friction>
            <bounce/>
          </surface>
          <max_contacts>10</max_contacts>
        </collision>
        <visual name='rotor_1_visual'>
          <pose frame=''>0.001879 -0.242705 -0.082217 0 -0 0</pose>
          <geometry>
            <mesh>
              <scale>0.001 0.001 0.001</scale>
              <uri>model://typhoon_h480/meshes/prop_cw_assembly_remeshed_v3.stl</uri>
            </mesh>
          </geometry>
          <material>
            <script>
              <name>Gazebo/DarkGrey</name>
              <uri>file://media/materials/scripts/gazebo.material</uri>
            </script>
          </material>
        </visual>
        <gravity>1</gravity>
        <velocity_decay/>
        <self_collide>0</self_collide>
        <enable_wind>1</enable_wind>
        <kinematic>0</kinematic>
      </link>
      <joint name='rotor_1_joint' type='revolute'>
        <child>rotor_1</child>
        <parent>base_link</parent>
        <axis>
          <xyz>0.0486 0.0811 1.8976</xyz>
          <limit>
            <lower>-1e+16</lower>
            <upper>1e+16</upper>
            <effort>10</effort>
            <velocity>-1</velocity>
          </limit>
          <dynamics>
            <damping>0.005</damping>
            <spring_reference>0</spring_reference>
            <spring_stiffness>0</spring_stiffness>
          </dynamics>
          <use_parent_model_frame>1</use_parent_model_frame>
        </axis>
        <physics>
          <ode>
            <implicit_spring_damper>1</implicit_spring_damper>
            <limit>
              <cfm>0</cfm>
              <erp>0.2</erp>
            </limit>
          </ode>
        </physics>
      </joint>
      <link name='rotor_5'>
        <pose frame=''>-0.001879 -0.242705 0.082217 0 0 -2.0944</pose>
        <inertial>
          <pose frame=''>0 0 0 0 -0 0</pose>
          <mass>0.005</mass>
          <inertia>
            <ixx>9.75e-07</ixx>
            <ixy>0</ixy>
            <ixz>0</ixz>
            <iyy>0.000273104</iyy>
            <iyz>0</iyz>
            <izz>0.000274004</izz>
          </inertia>
        </inertial>
        <collision name='rotor_5_collision'>
          <pose frame=''>0 0 0 0 -0 0</pose>
          <geometry>
            <cylinder>
              <length>0.005</length>
              <radius>0.128</radius>
            </cylinder>
          </geometry>
          <surface>
            <contact>
              <ode/>
            </contact>
            <friction>
              <ode/>
              <torsional>
                <ode/>
              </torsional>
            </friction>
            <bounce/>
          </surface>
          <max_contacts>10</max_contacts>
        </collision>
        <visual name='rotor_5_visual'>
          <pose frame=''>-0.211396 -0.119762 -0.082219 0 -0 0</pose>
          <geometry>
            <mesh>
              <scale>0.001 0.001 0.001</scale>
              <uri>model://typhoon_h480/meshes/prop_ccw_assembly_remeshed_v3.stl</uri>
            </mesh>
          </geometry>
          <material>
            <script>
              <name>Gazebo/Blue</name>
              <uri>file://media/materials/scripts/gazebo.material</uri>
            </script>
          </material>
        </visual>
        <gravity>1</gravity>
        <velocity_decay/>
        <self_collide>0</self_collide>
        <enable_wind>1</enable_wind>
        <kinematic>0</kinematic>
      </link>
      <joint name='rotor_5_joint' type='revolute'>
        <child>rotor_5</child>
        <parent>base_link</parent>
        <axis>
          <xyz>-0.033996 -0.0006 0.68216</xyz>
          <limit>
            <lower>-1e+16</lower>
            <upper>1e+16</upper>
            <effort>10</effort>
            <velocity>-1</velocity>
          </limit>
          <dynamics>
            <damping>0.005</damping>
            <spring_reference>0</spring_reference>
            <spring_stiffness>0</spring_stiffness>
          </dynamics>
          <use_parent_model_frame>1</use_parent_model_frame>
        </axis>
        <physics>
          <ode>
            <implicit_spring_damper>1</implicit_spring_damper>
            <limit>
              <cfm>0</cfm>
              <erp>0.2</erp>
            </limit>
          </ode>
        </physics>
      </joint>
      <link name='rotor_2'>
        <pose frame=''>-0.209396 -0.122762 0.082219 0 -0 2.0944</pose>
        <inertial>
          <pose frame=''>0 0 0 0 -0 0</pose>
          <mass>0.005</mass>
          <inertia>
            <ixx>9.75e-07</ixx>
            <ixy>0</ixy>
            <ixz>0</ixz>
            <iyy>0.000273104</iyy>
            <iyz>0</iyz>
            <izz>0.000274004</izz>
          </inertia>
        </inertial>
        <collision name='rotor_2_collision'>
          <pose frame=''>0 0 0 0 -0 0</pose>
          <geometry>
            <cylinder>
              <length>0.005</length>
              <radius>0.128</radius>
            </cylinder>
          </geometry>
          <surface>
            <contact>
              <ode/>
            </contact>
            <friction>
              <ode/>
              <torsional>
                <ode/>
              </torsional>
            </friction>
            <bounce/>
          </surface>
          <max_contacts>10</max_contacts>
        </collision>
        <visual name='rotor_2_visual'>
          <pose frame=''>0.001879 -0.242705 -0.082217 0 -0 0</pose>
          <geometry>
            <mesh>
              <scale>0.001 0.001 0.001</scale>
              <uri>model://typhoon_h480/meshes/prop_cw_assembly_remeshed_v3.stl</uri>
            </mesh>
          </geometry>
          <material>
            <script>
              <name>Gazebo/DarkGrey</name>
              <uri>file://media/materials/scripts/gazebo.material</uri>
            </script>
          </material>
        </visual>
        <gravity>1</gravity>
        <velocity_decay/>
        <self_collide>0</self_collide>
        <enable_wind>1</enable_wind>
        <kinematic>0</kinematic>
      </link>
      <joint name='rotor_2_joint' type='revolute'>
        <child>rotor_2</child>
        <parent>base_link</parent>
        <axis>
          <xyz>0.0404 -0.0876 1.8976</xyz>
          <limit>
            <lower>-1e+16</lower>
            <upper>1e+16</upper>
            <effort>10</effort>
            <velocity>-1</velocity>
          </limit>
          <dynamics>
            <damping>0.005</damping>
            <spring_reference>0</spring_reference>
            <spring_stiffness>0</spring_stiffness>
          </dynamics>
          <use_parent_model_frame>1</use_parent_model_frame>
        </axis>
        <physics>
          <ode>
            <implicit_spring_damper>1</implicit_spring_damper>
            <limit>
              <cfm>0</cfm>
              <erp>0.2</erp>
            </limit>
          </ode>
        </physics>
      </joint>
      <link name='sonar_model::link'>
        <pose frame=''>0 0 0 0 -0 0</pose>
        <inertial>
          <pose frame=''>0 0 0 0 -0 0</pose>
          <mass>1e-15</mass>
          <inertia>
            <ixx>2.08333e-07</ixx>
            <ixy>0</ixy>
            <ixz>0</ixz>
            <iyy>2.08333e-07</iyy>
            <iyz>0</iyz>
            <izz>4.16667e-08</izz>
          </inertia>
        </inertial>
        <visual name='visual'>
          <geometry>
            <box>
              <size>0.005 0.015 0.005</size>
            </box>
          </geometry>
          <material>
            <script>
              <uri>__default__</uri>
              <name>__default__</name>
            </script>
          </material>
        </visual>
        <sensor name='sonar' type='sonar'>
          <pose frame=''>0 0 0 1.5707 -1.5707 1.5707</pose>
          <sonar>
            <min>0.02</min>
            <max>5</max>
            <radius>1.33974</radius>
          </sonar>
          <always_on>1</always_on>
          <update_rate>20</update_rate>
          <visualize>1</visualize>
          <plugin name='SonarPlugin' filename='libgazebo_sonar_plugin.so'/>
          <always_on>1</always_on>
          <update_rate>20</update_rate>
          <visualize>1</visualize>
        </sensor>
        <self_collide>0</self_collide>
        <enable_wind>1</enable_wind>
        <kinematic>0</kinematic>
      </link>
      <joint name='sonar_joint' type='revolute'>
        <child>sonar_model::link</child>
        <parent>typhoon_h480::base_link</parent>
        <axis>
          <xyz>0 0 1</xyz>
          <limit>
            <upper>0</upper>
            <lower>0</lower>
          </limit>
          <use_parent_model_frame>0</use_parent_model_frame>
          <dynamics>
            <spring_reference>0</spring_reference>
            <spring_stiffness>0</spring_stiffness>
          </dynamics>
        </axis>
      </joint>
      <link name='lidar::link'>
        <inertial>
          <pose frame=''>0 0 0 0 -0 0</pose>
          <mass>0.01</mass>
          <inertia>
            <ixx>2.1733e-06</ixx>
            <ixy>0</ixy>
            <ixz>0</ixz>
            <iyy>2.1733e-06</iyy>
            <iyz>0</iyz>
            <izz>1.8e-07</izz>
          </inertia>
        </inertial>
        <visual name='visual'>
          <geometry>
            <cylinder>
              <radius>0.006</radius>
              <length>0.05</length>
            </cylinder>
          </geometry>
          <material>
            <script>
              <uri>__default__</uri>
              <name>__default__</name>
            </script>
          </material>
        </visual>
        <sensor name='laser' type='ray'>
          <pose frame=''>0 0 0 3.14159 -1.5707 3.14159</pose>
          <ray>
            <scan>
              <horizontal>
                <samples>1</samples>
                <resolution>1</resolution>
                <min_angle>-0</min_angle>
                <max_angle>0</max_angle>
              </horizontal>
              <vertical>
                <samples>1</samples>
                <min_angle>0</min_angle>
                <max_angle>0</max_angle>
              </vertical>
            </scan>
            <range>
              <min>0.06</min>
              <max>25</max>
              <resolution>0.05</resolution>
            </range>
          </ray>
          <visualize>1</visualize>
          <plugin name='LaserPlugin' filename='libgazebo_lidar_plugin.so'/>
          <always_on>1</always_on>
          <update_rate>125</update_rate>
        </sensor>
        <pose frame=''>0.05 0 -0.08 3.14159 0.001593 3.14159</pose>
        <self_collide>0</self_collide>
        <enable_wind>1</enable_wind>
        <kinematic>0</kinematic>
      </link>
      <joint name='lidar_joint' type='fixed'>
        <child>lidar::link</child>
        <parent>typhoon_h480::base_link</parent>
        <axis>
          <xyz>0 0 0</xyz>
          <limit>
            <upper>0</upper>
            <lower>0</lower>
          </limit>
          <use_parent_model_frame>0</use_parent_model_frame>
        </axis>
      </joint>
      <plugin name='rosbag' filename='librotors_gazebo_multirotor_base_plugin.so'>
        <robotNamespace/>
        <linkName>base_link</linkName>
        <rotorVelocitySlowdownSim>10</rotorVelocitySlowdownSim>
      </plugin>
      <plugin name='front_right_motor_model' filename='librotors_gazebo_motor_model.so'>
        <robotNamespace/>
        <jointName>rotor_0_joint</jointName>
        <linkName>rotor_0</linkName>
        <turningDirection>ccw</turningDirection>
        <timeConstantUp>0.0125</timeConstantUp>
        <timeConstantDown>0.025</timeConstantDown>
        <maxRotVelocity>1500</maxRotVelocity>
        <motorConstant>8.54858e-06</motorConstant>
        <momentConstant>0.06</momentConstant>
        <commandSubTopic>/gazebo/command/motor_speed</commandSubTopic>
        <motorNumber>4</motorNumber>
        <rotorDragCoefficient>0.000806428</rotorDragCoefficient>
        <rollingMomentCoefficient>1e-06</rollingMomentCoefficient>
        <motorSpeedPubTopic>/motor_speed/4</motorSpeedPubTopic>
        <rotorVelocitySlowdownSim>10</rotorVelocitySlowdownSim>
      </plugin>
      <plugin name='back_left_motor_model' filename='librotors_gazebo_motor_model.so'>
        <robotNamespace/>
        <jointName>rotor_1_joint</jointName>
        <linkName>rotor_1</linkName>
        <turningDirection>cw</turningDirection>
        <timeConstantUp>0.0125</timeConstantUp>
        <timeConstantDown>0.025</timeConstantDown>
        <maxRotVelocity>1500</maxRotVelocity>
        <motorConstant>8.54858e-06</motorConstant>
        <momentConstant>0.06</momentConstant>
        <commandSubTopic>/gazebo/command/motor_speed</commandSubTopic>
        <motorNumber>5</motorNumber>
        <rotorDragCoefficient>0.000806428</rotorDragCoefficient>
        <rollingMomentCoefficient>1e-06</rollingMomentCoefficient>
        <motorSpeedPubTopic>/motor_speed/5</motorSpeedPubTopic>
        <rotorVelocitySlowdownSim>10</rotorVelocitySlowdownSim>
      </plugin>
      <plugin name='front_left_motor_model' filename='librotors_gazebo_motor_model.so'>
        <robotNamespace/>
        <jointName>rotor_2_joint</jointName>
        <linkName>rotor_2</linkName>
        <turningDirection>cw</turningDirection>
        <timeConstantUp>0.0125</timeConstantUp>
        <timeConstantDown>0.025</timeConstantDown>
        <maxRotVelocity>1500</maxRotVelocity>
        <motorConstant>8.54858e-06</motorConstant>
        <momentConstant>0.06</momentConstant>
        <commandSubTopic>/gazebo/command/motor_speed</commandSubTopic>
        <motorNumber>2</motorNumber>
        <rotorDragCoefficient>0.000806428</rotorDragCoefficient>
        <rollingMomentCoefficient>1e-06</rollingMomentCoefficient>
        <motorSpeedPubTopic>/motor_speed/2</motorSpeedPubTopic>
        <rotorVelocitySlowdownSim>10</rotorVelocitySlowdownSim>
      </plugin>
      <plugin name='back_right_motor_model' filename='librotors_gazebo_motor_model.so'>
        <robotNamespace/>
        <jointName>rotor_3_joint</jointName>
        <linkName>rotor_3</linkName>
        <turningDirection>ccw</turningDirection>
        <timeConstantUp>0.0125</timeConstantUp>
        <timeConstantDown>0.025</timeConstantDown>
        <maxRotVelocity>1500</maxRotVelocity>
        <motorConstant>8.54858e-06</motorConstant>
        <momentConstant>0.06</momentConstant>
        <commandSubTopic>/gazebo/command/motor_speed</commandSubTopic>
        <motorNumber>3</motorNumber>
        <rotorDragCoefficient>0.000806428</rotorDragCoefficient>
        <rollingMomentCoefficient>1e-06</rollingMomentCoefficient>
        <motorSpeedPubTopic>/motor_speed/3</motorSpeedPubTopic>
        <rotorVelocitySlowdownSim>10</rotorVelocitySlowdownSim>
      </plugin>
      <plugin name='back_left_motor_model' filename='librotors_gazebo_motor_model.so'>
        <robotNamespace/>
        <jointName>rotor_4_joint</jointName>
        <linkName>rotor_4</linkName>
        <turningDirection>cw</turningDirection>
        <timeConstantUp>0.0125</timeConstantUp>
        <timeConstantDown>0.025</timeConstantDown>
        <maxRotVelocity>1500</maxRotVelocity>
        <motorConstant>8.54858e-06</motorConstant>
        <momentConstant>0.06</momentConstant>
        <commandSubTopic>/gazebo/command/motor_speed</commandSubTopic>
        <motorNumber>0</motorNumber>
        <rotorDragCoefficient>0.000806428</rotorDragCoefficient>
        <rollingMomentCoefficient>1e-06</rollingMomentCoefficient>
        <motorSpeedPubTopic>/motor_speed/0</motorSpeedPubTopic>
        <rotorVelocitySlowdownSim>10</rotorVelocitySlowdownSim>
      </plugin>
      <plugin name='front_left_motor_model' filename='librotors_gazebo_motor_model.so'>
        <robotNamespace/>
        <jointName>rotor_5_joint</jointName>
        <linkName>rotor_5</linkName>
        <turningDirection>ccw</turningDirection>
        <timeConstantUp>0.0125</timeConstantUp>
        <timeConstantDown>0.025</timeConstantDown>
        <maxRotVelocity>1500</maxRotVelocity>
        <motorConstant>8.54858e-06</motorConstant>
        <momentConstant>0.06</momentConstant>
        <commandSubTopic>/gazebo/command/motor_speed</commandSubTopic>
        <motorNumber>1</motorNumber>
        <rotorDragCoefficient>0.000806428</rotorDragCoefficient>
        <rollingMomentCoefficient>1e-06</rollingMomentCoefficient>
        <motorSpeedPubTopic>/motor_speed/1</motorSpeedPubTopic>
        <rotorVelocitySlowdownSim>10</rotorVelocitySlowdownSim>
      </plugin>
      <plugin name='mavlink_interface' filename='librotors_gazebo_mavlink_interface.so'>
        <robotNamespace/>
        <imuSubTopic>/imu</imuSubTopic>
        <motorSpeedCommandPubTopic>/gazebo/command/motor_speed</motorSpeedCommandPubTopic>
        <control_channels>
          <channel name='rotor0'>
            <input_index>0</input_index>
            <input_offset>0</input_offset>
            <input_scaling>1500</input_scaling>
            <zero_position_disarmed>0</zero_position_disarmed>
            <zero_position_armed>100</zero_position_armed>
            <joint_control_type>velocity</joint_control_type>
            <joint_name>rotor_4_joint</joint_name>
          </channel>
          <channel name='rotor1'>
            <input_index>1</input_index>
            <input_offset>0</input_offset>
            <input_scaling>1500</input_scaling>
            <zero_position_disarmed>0</zero_position_disarmed>
            <zero_position_armed>100</zero_position_armed>
            <joint_control_type>velocity</joint_control_type>
            <joint_name>rotor_5_joint</joint_name>
          </channel>
          <channel name='rotor2'>
            <input_index>2</input_index>
            <input_offset>0</input_offset>
            <input_scaling>1500</input_scaling>
            <zero_position_disarmed>0</zero_position_disarmed>
            <zero_position_armed>100</zero_position_armed>
            <joint_control_type>velocity</joint_control_type>
            <joint_name>rotor_2_joint</joint_name>
          </channel>
          <channel name='rotor3'>
            <input_index>3</input_index>
            <input_offset>0</input_offset>
            <input_scaling>1500</input_scaling>
            <zero_position_disarmed>0</zero_position_disarmed>
            <zero_position_armed>100</zero_position_armed>
            <joint_control_type>velocity</joint_control_type>
            <joint_name>rotor_3_joint</joint_name>
          </channel>
          <channel name='rotor4'>
            <input_index>4</input_index>
            <input_offset>0</input_offset>
            <input_scaling>1500</input_scaling>
            <zero_position_disarmed>0</zero_position_disarmed>
            <zero_position_armed>100</zero_position_armed>
            <joint_control_type>velocity</joint_control_type>
            <joint_name>rotor_0_joint</joint_name>
          </channel>
          <channel name='rotor5'>
            <input_index>5</input_index>
            <input_offset>0</input_offset>
            <input_scaling>1500</input_scaling>
            <zero_position_disarmed>0</zero_position_disarmed>
            <zero_position_armed>100</zero_position_armed>
            <joint_control_type>velocity</joint_control_type>
            <joint_name>rotor_1_joint</joint_name>
          </channel>
          <channel name='gimbal_roll'>
            <input_index>6</input_index>
            <input_offset>0</input_offset>
            <input_scaling>-3.1415</input_scaling>
            <zero_position_disarmed>0</zero_position_disarmed>
            <zero_position_armed>0</zero_position_armed>
            <joint_control_type>position_gztopic</joint_control_type>
            <gztopic>/gimbal_roll_cmd</gztopic>
            <joint_name>typhoon_h480::cgo3_camera_joint</joint_name>
          </channel>
          <channel name='gimbal_pitch'>
            <input_index>7</input_index>
            <input_offset>0</input_offset>
            <input_scaling>3.1415</input_scaling>
            <zero_position_disarmed>0</zero_position_disarmed>
            <zero_position_armed>0</zero_position_armed>
            <joint_control_type>position_gztopic</joint_control_type>
            <gztopic>/gimbal_pitch_cmd</gztopic>
            <joint_name>typhoon_h480::cgo3_camera_joint</joint_name>
          </channel>
          <channel name='gimbal_yaw'>
            <input_index>8</input_index>
            <input_offset>0</input_offset>
            <input_scaling>-3.1415</input_scaling>
            <zero_position_disarmed>0</zero_position_disarmed>
            <zero_position_armed>0</zero_position_armed>
            <joint_control_type>position_gztopic</joint_control_type>
            <gztopic>/gimbal_yaw_cmd</gztopic>
            <joint_name>typhoon_h480::cgo3_vertical_arm_joint</joint_name>
          </channel>
          <channel name='left_leg'>
            <input_index>9</input_index>
            <input_offset>1</input_offset>
            <input_scaling>0.5</input_scaling>
            <zero_position_disarmed>0</zero_position_disarmed>
            <zero_position_armed>0</zero_position_armed>
            <joint_control_type>position</joint_control_type>
            <joint_control_pid>
              <p>3.5</p>
              <i>0.5</i>
              <d>0</d>
              <iMax>4</iMax>
              <iMin>-4</iMin>
              <cmdMax>6</cmdMax>
              <cmdMin>-6</cmdMin>
            </joint_control_pid>
            <joint_name>left_leg_joint</joint_name>
          </channel>
          <channel name='right_leg'>
            <input_index>10</input_index>
            <input_offset>1</input_offset>
            <input_scaling>0.5</input_scaling>
            <zero_position_disarmed>0</zero_position_disarmed>
            <zero_position_armed>0</zero_position_armed>
            <joint_control_type>position</joint_control_type>
            <joint_control_pid>
              <p>3.5</p>
              <i>0.5</i>
              <d>0</d>
              <iMax>4</iMax>
              <iMin>-4</iMin>
              <cmdMax>6</cmdMax>
              <cmdMin>-6</cmdMin>
            </joint_control_pid>
            <joint_name>right_leg_joint</joint_name>
          </channel>
        </control_channels>
      </plugin>
      <static>0</static>
      <plugin name='rotors_gazebo_imu_plugin' filename='librotors_gazebo_imu_plugin.so'>
        <robotNamespace/>
        <linkName>typhoon_h480/imu_link</linkName>
        <imuTopic>/imu</imuTopic>
        <gyroscopeNoiseDensity>0.0003394</gyroscopeNoiseDensity>
        <gyroscopeRandomWalk>3.8785e-05</gyroscopeRandomWalk>
        <gyroscopeBiasCorrelationTime>1000.0</gyroscopeBiasCorrelationTime>
        <gyroscopeTurnOnBiasSigma>0.0087</gyroscopeTurnOnBiasSigma>
        <accelerometerNoiseDensity>0.004</accelerometerNoiseDensity>
        <accelerometerRandomWalk>0.006</accelerometerRandomWalk>
        <accelerometerBiasCorrelationTime>300.0</accelerometerBiasCorrelationTime>
        <accelerometerTurnOnBiasSigma>0.196</accelerometerTurnOnBiasSigma>
      </plugin>
      <plugin name='gimbal_controller' filename='librotors_gazebo_gimbal_controller_plugin.so'>
        <joint_yaw>typhoon_h480::cgo3_vertical_arm_joint</joint_yaw>
        <joint_roll>typhoon_h480::cgo3_horizontal_arm_joint</joint_roll>
        <joint_pitch>typhoon_h480::cgo3_camera_joint</joint_pitch>
        <imu>camera_imu</imu>
      </plugin>
    </model>
    <model name='asphalt_plane'>
      <static>1</static>
      <link name='link'>
        <collision name='collision'>
          <geometry>
            <box>
              <size>200 200 0.1</size>
            </box>
          </geometry>
          <max_contacts>10</max_contacts>
          <surface>
            <contact>
              <ode/>
            </contact>
            <bounce/>
            <friction>
              <torsional>
                <ode/>
              </torsional>
              <ode/>
            </friction>
          </surface>
        </collision>
        <visual name='visual'>
          <cast_shadows>0</cast_shadows>
          <geometry>
            <box>
              <size>200 200 0.1</size>
            </box>
          </geometry>
          <material>
            <script>
              <uri>model://asphalt_plane/materials/scripts</uri>
              <uri>model://asphalt_plane/materials/textures</uri>
              <name>vrc/asphalt</name>
            </script>
          </material>
        </visual>
        <self_collide>0</self_collide>
        <enable_wind>1</enable_wind>
        <kinematic>0</kinematic>
      </link>
    </model>
    <physics name='default_physics' default='0' type='ode'>
      <ode>
        <solver>
          <type>quick</type>
          <iters>50</iters>
          <sor>1</sor>
          <use_dynamic_moi_rescaling>0</use_dynamic_moi_rescaling>
        </solver>
        <constraints>
          <cfm>0</cfm>
          <erp>0.2</erp>
          <contact_max_correcting_vel>100</contact_max_correcting_vel>
          <contact_surface_layer>0.001</contact_surface_layer>
        </constraints>
      </ode>
      <max_step_size>0.002</max_step_size>
      <real_time_factor>1</real_time_factor>
      <real_time_update_rate>500</real_time_update_rate>
    </physics>
    <gravity>0 0 -9.8066</gravity>
    <magnetic_field>6e-06 2.3e-05 -4.2e-05</magnetic_field>
    <atmosphere type='adiabatic'/>
    <scene>
      <ambient>0.4 0.4 0.4 1</ambient>
      <background>0.7 0.7 0.7 1</background>
      <shadows>1</shadows>
    </scene>
    <wind/>
    <spherical_coordinates>
      <surface_model>EARTH_WGS84</surface_model>
      <latitude_deg>0</latitude_deg>
      <longitude_deg>0</longitude_deg>
      <elevation>0</elevation>
      <heading_deg>0</heading_deg>
    </spherical_coordinates>
    <model name='oak_tree'>
      <static>1</static>
      <link name='link'>
        <collision name='collision'>
          <geometry>
            <mesh>
              <uri>model://oak_tree/meshes/oak_tree.dae</uri>
            </mesh>
          </geometry>
          <max_contacts>10</max_contacts>
          <surface>
            <contact>
              <ode/>
            </contact>
            <bounce/>
            <friction>
              <torsional>
                <ode/>
              </torsional>
              <ode/>
            </friction>
          </surface>
        </collision>
        <visual name='branch'>
          <geometry>
            <mesh>
              <uri>model://oak_tree/meshes/oak_tree.dae</uri>
              <submesh>
                <name>Branch</name>
              </submesh>
            </mesh>
          </geometry>
          <material>
            <script>
              <uri>model://oak_tree/materials/scripts/</uri>
              <uri>model://oak_tree/materials/textures/</uri>
              <name>OakTree/Branch</name>
            </script>
          </material>
        </visual>
        <visual name='bark'>
          <geometry>
            <mesh>
              <uri>model://oak_tree/meshes/oak_tree.dae</uri>
              <submesh>
                <name>Bark</name>
              </submesh>
            </mesh>
          </geometry>
          <material>
            <script>
              <uri>model://oak_tree/materials/scripts/</uri>
              <uri>model://oak_tree/materials/textures/</uri>
              <name>OakTree/Bark</name>
            </script>
          </material>
        </visual>
        <self_collide>0</self_collide>
        <enable_wind>1</enable_wind>
        <kinematic>0</kinematic>
      </link>
      <pose frame=''>3.32318 -11.8254 0 0 -0 0</pose>
    </model>
    <model name='pine_tree'>
      <static>1</static>
      <link name='link'>
        <collision name='collision'>
          <geometry>
            <mesh>
              <uri>model://pine_tree/meshes/pine_tree.dae</uri>
            </mesh>
          </geometry>
          <max_contacts>10</max_contacts>
          <surface>
            <contact>
              <ode/>
            </contact>
            <bounce/>
            <friction>
              <torsional>
                <ode/>
              </torsional>
              <ode/>
            </friction>
          </surface>
        </collision>
        <visual name='branch'>
          <geometry>
            <mesh>
              <uri>model://pine_tree/meshes/pine_tree.dae</uri>
              <submesh>
                <name>Branch</name>
              </submesh>
            </mesh>
          </geometry>
          <material>
            <script>
              <uri>model://pine_tree/materials/scripts/</uri>
              <uri>model://pine_tree/materials/textures/</uri>
              <name>PineTree/Branch</name>
            </script>
          </material>
        </visual>
        <visual name='bark'>
          <geometry>
            <mesh>
              <uri>model://pine_tree/meshes/pine_tree.dae</uri>
              <submesh>
                <name>Bark</name>
              </submesh>
            </mesh>
          </geometry>
          <material>
            <script>
              <uri>model://pine_tree/materials/scripts/</uri>
              <uri>model://pine_tree/materials/textures/</uri>
              <name>PineTree/Bark</name>
            </script>
          </material>
        </visual>
        <self_collide>0</self_collide>
        <enable_wind>1</enable_wind>
        <kinematic>0</kinematic>
      </link>
      <pose frame=''>11.6166 -9.2063 0 0 -0 0</pose>
    </model>
    <model name='pickup'>
      <static>1</static>
      <link name='link'>
        <collision name='collision'>
          <pose frame=''>0 0 0 0 0 -1.5708</pose>
          <geometry>
            <mesh>
              <uri>model://pickup/meshes/pickup.dae</uri>
            </mesh>
          </geometry>
          <max_contacts>10</max_contacts>
          <surface>
            <contact>
              <ode/>
            </contact>
            <bounce/>
            <friction>
              <torsional>
                <ode/>
              </torsional>
              <ode/>
            </friction>
          </surface>
        </collision>
        <visual name='visual'>
          <pose frame=''>0 0 0 0 0 -1.5708</pose>
          <geometry>
            <mesh>
              <uri>model://pickup/meshes/pickup.dae</uri>
            </mesh>
          </geometry>
        </visual>
        <self_collide>0</self_collide>
        <enable_wind>1</enable_wind>
        <kinematic>0</kinematic>
      </link>
      <pose frame=''>9.93253 -15.8453 0 0 -0 0</pose>
    </model>
    <model name='person_standing'>
      <link name='link'>
        <inertial>
          <pose frame=''>0 -0.1 0.95 0 -0 0</pose>
          <mass>80</mass>
          <inertia>
            <ixx>24.88</ixx>
            <ixy>0</ixy>
            <ixz>0</ixz>
            <iyy>25.73</iyy>
            <iyz>0</iyz>
            <izz>2.48</izz>
          </inertia>
        </inertial>
        <collision name='bottom'>
          <pose frame=''>0 -0.1 0.01 0 -0 0</pose>
          <geometry>
            <box>
              <size>0.5 0.35 0.02</size>
            </box>
          </geometry>
          <max_contacts>10</max_contacts>
          <surface>
            <contact>
              <ode/>
            </contact>
            <bounce/>
            <friction>
              <torsional>
                <ode/>
              </torsional>
              <ode/>
            </friction>
          </surface>
        </collision>
        <collision name='person'>
          <pose frame=''>0 0 0.02 0.04 -0 0</pose>
          <geometry>
            <mesh>
              <uri>model://person_standing/meshes/standing.dae</uri>
            </mesh>
          </geometry>
          <max_contacts>10</max_contacts>
          <surface>
            <contact>
              <ode/>
            </contact>
            <bounce/>
            <friction>
              <torsional>
                <ode/>
              </torsional>
              <ode/>
            </friction>
          </surface>
        </collision>
        <visual name='visual'>
          <pose frame=''>0 0 0.02 0.04 -0 0</pose>
          <geometry>
            <mesh>
              <uri>model://person_standing/meshes/standing.dae</uri>
            </mesh>
          </geometry>
        </visual>
        <self_collide>0</self_collide>
        <enable_wind>1</enable_wind>
        <kinematic>0</kinematic>
      </link>
      <pose frame=''>15.9227 -11.9246 0 0 -0 0</pose>
    </model>
    <model name='parrot_bebop_2'>
      <static>0</static>
      <pose frame=''>14.4721 -12.9111 0.062656 0 -0 0</pose>
      <link name='body'>
        <inertial>
          <mass>0.503</mass>
          <inertia>
            <ixx>0.001805</ixx>
            <ixy>-8.619e-07</ixy>
            <iyy>0.001764</iyy>
            <ixz>1.555e-05</ixz>
            <iyz>3.595e-07</iyz>
            <izz>0.003328</izz>
          </inertia>
          <pose frame=''>0 0 0 0 -0 0</pose>
        </inertial>
        <collision name='collision'>
          <pose frame=''>-0.00424 0.00014 -0.00595 0 -0 0</pose>
          <geometry>
            <box>
              <size>0.316618 0.330564 0.089582</size>
            </box>
          </geometry>
          <max_contacts>10</max_contacts>
          <surface>
            <bounce>
              <restitution_coefficient>0.828</restitution_coefficient>
              <threshold>0</threshold>
            </bounce>
            <friction>
              <ode>
                <mu>10</mu>
                <mu2>5</mu2>
                <fdir1>0 0 0</fdir1>
                <slip1>0</slip1>
                <slip2>0</slip2>
              </ode>
              <torsional>
                <ode/>
              </torsional>
            </friction>
            <contact>
              <ode>
                <kp>10000</kp>
                <kd>10</kd>
                <max_vel>0.01</max_vel>
                <min_depth>0</min_depth>
              </ode>
            </contact>
          </surface>
        </collision>
        <visual name='hull'>
          <geometry>
            <mesh>
              <uri>model://parrot_bebop_2/meshes/hull.dae</uri>
            </mesh>
          </geometry>
        </visual>
        <visual name='propeller_rr'>
          <pose frame=''>-0.09035 -0.11423 -0.00501 0 -0 0</pose>
          <geometry>
            <mesh>
              <uri>model://parrot_bebop_2/meshes/propeller_rr.dae</uri>
            </mesh>
          </geometry>
        </visual>
        <visual name='propeller_rl'>
          <pose frame=''>-0.09035 0.11452 -0.00501 0 -0 0</pose>
          <geometry>
            <mesh>
              <uri>model://parrot_bebop_2/meshes/propeller_rl.dae</uri>
            </mesh>
          </geometry>
        </visual>
        <visual name='propeller_fr'>
          <pose frame=''>0.08456 -0.11435 -0.00501 0 -0 0</pose>
          <geometry>
            <mesh>
              <uri>model://parrot_bebop_2/meshes/propeller_fr.dae</uri>
            </mesh>
          </geometry>
        </visual>
        <visual name='propeller_fl'>
          <pose frame=''>0.08456 0.11463 -0.00501 0 -0 0</pose>
          <geometry>
            <mesh>
              <uri>model://parrot_bebop_2/meshes/propeller_fl.dae</uri>
            </mesh>
          </geometry>
        </visual>
        <self_collide>0</self_collide>
        <enable_wind>1</enable_wind>
        <kinematic>0</kinematic>
      </link>
    </model>
    <model name='vrc_driving_terrain'>
      <static>1</static>
      <link name='link'>
        <collision name='collision'>
          <geometry>
            <heightmap>
              <uri>model://vrc_driving_terrain/materials/textures/heightmap.png</uri>
              <size>500 500 118</size>
              <pos>0 0 -15</pos>
              <texture>
                <size>10</size>
                <diffuse>__default__</diffuse>
                <normal>__default__</normal>
              </texture>
              <blend>
                <min_height>0</min_height>
                <fade_dist>0</fade_dist>
              </blend>
            </heightmap>
          </geometry>
          <max_contacts>10</max_contacts>
          <surface>
            <contact>
              <ode/>
            </contact>
            <bounce/>
            <friction>
              <torsional>
                <ode/>
              </torsional>
              <ode/>
            </friction>
          </surface>
        </collision>
        <visual name='visual'>
          <geometry>
            <heightmap>
              <texture>
                <diffuse>file://media/materials/textures/dirt_diffusespecular.png</diffuse>
                <normal>file://media/materials/textures/flat_normal.png</normal>
                <size>5</size>
              </texture>
              <texture>
                <diffuse>file://media/materials/textures/grass_diffusespecular.png</diffuse>
                <normal>file://media/materials/textures/flat_normal.png</normal>
                <size>5</size>
              </texture>
              <texture>
                <diffuse>file://media/materials/textures/fungus_diffusespecular.png</diffuse>
                <normal>file://media/materials/textures/flat_normal.png</normal>
                <size>20</size>
              </texture>
              <blend>
                <min_height>15</min_height>
                <fade_dist>5</fade_dist>
              </blend>
              <blend>
                <min_height>30</min_height>
                <fade_dist>10</fade_dist>
              </blend>
              <uri>model://vrc_driving_terrain/materials/textures/heightmap.png</uri>
              <size>500 500 118</size>
              <pos>0 0 -15</pos>
            </heightmap>
          </geometry>
        </visual>
        <self_collide>0</self_collide>
        <enable_wind>1</enable_wind>
        <kinematic>0</kinematic>
      </link>
      <link name='grass_plane'>
        <collision name='collision'>
          <geometry>
            <plane>
              <normal>0 0 1</normal>
              <size>500 500</size>
            </plane>
          </geometry>
          <surface>
            <friction>
              <ode>
                <mu>0.5</mu>
                <mu2>0.5</mu2>
              </ode>
              <torsional>
                <ode/>
              </torsional>
            </friction>
            <contact>
              <ode/>
            </contact>
            <bounce/>
          </surface>
          <max_contacts>10</max_contacts>
        </collision>
        <visual name='visual_0'>
          <pose frame=''>0 0 0 0 -0 0</pose>
          <cast_shadows>0</cast_shadows>
          <geometry>
            <plane>
              <normal>0 0 1</normal>
              <size>500 500</size>
            </plane>
          </geometry>
          <material>
            <script>
              <uri>model://vrc_driving_terrain/materials/scripts</uri>
              <uri>model://vrc_driving_terrain/materials/textures</uri>
              <name>vrc/grass</name>
            </script>
          </material>
        </visual>
        <self_collide>0</self_collide>
        <enable_wind>1</enable_wind>
        <kinematic>0</kinematic>
      </link>
      <pose frame=''>16.2675 -10.652 0 0 -0 0</pose>
    </model>
    <state world_name='default'>
      <sim_time>25492 166000000</sim_time>
      <real_time>25606 767947696</real_time>
      <wall_time>1524704939 691540149</wall_time>
      <iterations>12746083</iterations>
      <model name='asphalt_plane'>
        <pose frame=''>0 0 -1.8 0 -0 0</pose>
        <scale>1 1 1</scale>
        <link name='link'>
          <pose frame=''>0 0 -1.8 0 -0 0</pose>
          <velocity>0 0 0 0 -0 0</velocity>
          <acceleration>0 0 0 0 -0 0</acceleration>
          <wrench>0 0 0 0 -0 0</wrench>
        </link>
      </model>
      <model name='ground_plane'>
        <pose frame=''>0 0 0 0 -0 0</pose>
        <scale>1 1 1</scale>
        <link name='link'>
          <pose frame=''>0 0 0 0 -0 0</pose>
          <velocity>0 0 0 0 -0 0</velocity>
          <acceleration>0 0 0 0 -0 0</acceleration>
          <wrench>0 0 0 0 -0 0</wrench>
        </link>
      </model>
      <model name='oak_tree'>
        <pose frame=''>3.32318 -11.8254 0 0 -0 0</pose>
        <scale>1 1 1</scale>
        <link name='link'>
          <pose frame=''>3.32318 -11.8254 0 0 -0 0</pose>
          <velocity>0 0 0 0 -0 0</velocity>
          <acceleration>0 0 0 0 -0 0</acceleration>
          <wrench>0 0 0 0 -0 0</wrench>
        </link>
      </model>
      <model name='parrot_bebop_2'>
        <pose frame=''>14.472 -12.9111 0.050649 1e-06 1.8e-05 0</pose>
        <scale>1 1 1</scale>
        <link name='body'>
          <pose frame=''>14.472 -12.9111 0.050649 1e-06 1.8e-05 0</pose>
          <velocity>0 0 0 0 -0 0</velocity>
          <acceleration>-0 -0 0 0 -0 0</acceleration>
          <wrench>-0 -0 0 0 -0 0</wrench>
        </link>
      </model>
      <model name='person_standing'>
        <pose frame=''>15.9204 -11.9246 -2e-06 -3e-06 -4e-06 0.023341</pose>
        <scale>1 1 1</scale>
        <link name='link'>
          <pose frame=''>15.9204 -11.9246 -2e-06 -3e-06 -4e-06 0.023341</pose>
          <velocity>0 0 0 0 -0 0</velocity>
          <acceleration>-1.62751 1.08899 -1.56175 1.98205 -1.43542 -3.09709</acceleration>
          <wrench>-130.201 87.1195 -124.94 0 -0 0</wrench>
        </link>
      </model>
      <model name='pickup'>
        <pose frame=''>9.93253 -15.8453 0 0 -0 0</pose>
        <scale>1 1 1</scale>
        <link name='link'>
          <pose frame=''>9.93253 -15.8453 0 0 -0 0</pose>
          <velocity>0 0 0 0 -0 0</velocity>
          <acceleration>0 0 0 0 -0 0</acceleration>
          <wrench>0 0 0 0 -0 0</wrench>
        </link>
      </model>
      <model name='pine_tree'>
        <pose frame=''>11.6166 -9.2063 0 0 -0 0</pose>
        <scale>1 1 1</scale>
        <link name='link'>
          <pose frame=''>11.6166 -9.2063 0 0 -0 0</pose>
          <velocity>0 0 0 0 -0 0</velocity>
          <acceleration>0 0 0 0 -0 0</acceleration>
          <wrench>0 0 0 0 -0 0</wrench>
        </link>
      </model>
      <model name='typhoon_h480'>
        <pose frame=''>-0.042381 -0.629175 0.218951 1.6e-05 -0.001395 2.33076</pose>
        <scale>1 1 1</scale>
        <link name='base_link'>
          <pose frame=''>-0.042381 -0.629175 0.218951 1.6e-05 -0.001395 2.33076</pose>
          <velocity>9.5e-05 9e-05 -0.00059 -0.001527 0.001887 -0.000478</velocity>
          <acceleration>-0.003477 0.012425 -0.23378 -0.110916 -0.844151 -0.233525</acceleration>
          <wrench>-0.007023 0.025099 -0.472235 0 -0 0</wrench>
        </link>
        <link name='cgo3_camera_link'>
          <pose frame=''>-0.050628 -0.647859 0.218893 -1.3e-05 7e-06 3.14153</pose>
          <velocity>-0.000256 -0.000153 -0.000693 -0.002135 0.001529 0.000867</velocity>
          <acceleration>-0.360158 -0.337954 -0.345826 -1.05673 0.246948 0.401819</acceleration>
          <wrench>-0.036016 -0.033795 -0.034583 0 -0 0</wrench>
        </link>
        <link name='cgo3_horizontal_arm_link'>
          <pose frame=''>-0.050468 -0.647859 0.218933 -1.3e-05 -0.000976 3.14153</pose>
          <velocity>-0.0002 -0.000156 -0.000674 -0.002135 0.001847 0.000867</velocity>
          <acceleration>-0.319053 -0.256007 -0.340838 -1.05672 0.463426 0.401826</acceleration>
          <wrench>-0.031905 -0.025601 -0.034084 0 -0 0</wrench>
        </link>
        <link name='cgo3_mount_link'>
          <pose frame=''>-0.04238 -0.629174 0.218948 2e-05 -0.001395 2.33076</pose>
          <velocity>-0.000102 -9.5e-05 -0.000649 -0.001582 0.001814 -0.000795</velocity>
          <acceleration>-0.274812 -0.241761 -0.280487 -0.351519 0.410478 -0.499415</acceleration>
          <wrench>-0.027481 -0.024176 -0.028049 0 -0 0</wrench>
        </link>
        <link name='cgo3_vertical_arm_link'>
          <pose frame=''>-0.050469 -0.648019 0.218935 -0.000998 -0.000977 3.14153</pose>
          <velocity>-0.000187 -0.000196 -0.000646 -0.001574 0.001715 0.000846</velocity>
          <acceleration>-0.324526 -0.293713 -0.315372 -0.347432 0.33392 0.382354</acceleration>
          <wrench>-0.032453 -0.029371 -0.031537 0 -0 0</wrench>
        </link>
        <link name='left_leg'>
          <pose frame=''>-0.042403 -0.629204 0.218956 3.3e-05 -0.00136 2.33085</pose>
          <velocity>-0.000879 -0.000856 -0.000814 0.003914 -0.004022 -2.3e-05</velocity>
          <acceleration>0.006732 0.006083 -0.003269 -0.499045 0.555027 0.002442</acceleration>
          <wrench>0.000673 0.000608 -0.000327 0 -0 0</wrench>
        </link>
        <link name='lidar::link'>
          <pose frame=''>-0.076901 -0.592851 0.13901 3.14157 0.002989 -0.810839</pose>
          <velocity>0.000379 0.00074 -0.000754 -0.001496 0.001863 -0.000487</velocity>
          <acceleration>-0.215851 -0.043694 -0.348622 -0.316637 0.488079 -0.256937</acceleration>
          <wrench>-0.002159 -0.000437 -0.003486 0 -0 0</wrench>
        </link>
        <link name='right_leg'>
          <pose frame=''>-0.042355 -0.629152 0.218954 1.9e-05 -0.001397 2.33069</pose>
          <velocity>0.000969 0.000895 -0.000853 -0.004075 0.004452 2.4e-05</velocity>
          <acceleration>0.003935 0.00358 -0.006111 -0.294297 0.344495 0.001688</acceleration>
          <wrench>0.000393 0.000358 -0.000611 0 -0 0</wrench>
        </link>
        <link name='rotor_0'>
          <pose frame=''>0.012965 -0.865611 0.300879 -0.085181 -0.050559 1.31612</pose>
          <velocity>0.000139 0.000192 -0.000343 -0.001567 0.009024 0.000231</velocity>
          <acceleration>-0.015185 0.027615 -0.194833 -2.81283 -0.377221 -1.45794</acceleration>
          <wrench>-7.6e-05 0.000138 -0.000974 0 -0 0</wrench>
        </link>
        <link name='rotor_1'>
          <pose frame=''>-0.101118 -0.393521 0.301462 0.003919 0.098753 -2.834</pose>
          <velocity>0.00037 0.000248 -0.000851 -0.001555 0.004693 6e-06</velocity>
          <acceleration>0.095283 0.054344 -0.281852 -2.39183 -1.26146 2.87396</acceleration>
          <wrench>0.000476 0.000272 -0.001409 0 -0 0</wrench>
        </link>
        <link name='rotor_2'>
          <pose frame=''>0.190936 -0.696471 0.300875 0.013508 0.100018 1.34482</pose>
          <velocity>0.000221 0.000105 -0.000941 -0.00153 0.00733 -0.000613</velocity>
          <acceleration>0.023954 -0.014214 -0.327572 1.97663 -0.253924 -2.19287</acceleration>
          <wrench>0.00012 -7.1e-05 -0.001638 0 -0 0</wrench>
        </link>
        <link name='rotor_3'>
          <pose frame=''>-0.274741 -0.558528 0.301466 -0.088276 -0.042695 -0.745378</pose>
          <velocity>0.00029 0.000333 -0.000266 -0.001531 0.001881 -9e-05</velocity>
          <acceleration>0.056906 0.095137 -0.151682 2.46746 0.6212 -0.585835</acceleration>
          <wrench>0.000285 0.000476 -0.000758 0 -0 0</wrench>
        </link>
        <link name='rotor_4'>
          <pose frame=''>-0.216934 -0.797817 0.301168 0.003151 0.102011 -0.743256</pose>
          <velocity>0.000173 0.000304 -8e-06 -0.001521 0.001862 6.6e-05</velocity>
          <acceleration>0.000823 0.081445 -0.107476 0.641435 1.05249 2.40638</acceleration>
          <wrench>4e-06 0.000407 -0.000537 0 -0 0</wrench>
        </link>
        <link name='rotor_5'>
          <pose frame=''>0.134922 -0.463422 0.30116 -0.088171 -0.049221 -2.84176</pose>
          <velocity>0.000335 0.000133 -0.001193 -0.00152 0.004518 0.000101</velocity>
          <acceleration>0.078607 -0.000981 -0.37069 -0.037015 0.513072 -0.781387</acceleration>
          <wrench>0.000393 -5e-06 -0.001853 0 -0 0</wrench>
        </link>
        <link name='sonar_model::link'>
          <pose frame=''>-0.042381 -0.629175 0.21895 1.6e-05 -0.001396 2.33076</pose>
          <velocity>9.8e-05 9.3e-05 -0.000601 -0.001531 0.0019 -0.000431</velocity>
          <acceleration>0.001459 0.015998 -0.242751 -0.312451 0.483817 -0.200809</acceleration>
          <wrench>0 0 -0 0 -0 0</wrench>
        </link>
        <link name='typhoon_h480/imu_link'>
          <pose frame=''>-0.042381 -0.629175 0.21895 -1.6e-05 0.001396 -0.810837</pose>
          <velocity>9.8e-05 9.3e-05 -0.000601 -0.001565 0.001935 -0.000487</velocity>
          <acceleration>0.001608 0.016123 -0.242955 -0.316222 0.489336 -0.23884</acceleration>
          <wrench>2.4e-05 0.000242 -0.003644 0 -0 0</wrench>
        </link>
      </model>
      <model name='vrc_driving_terrain'>
        <pose frame=''>16.2675 -10.652 2 0 -0 0</pose>
        <scale>1 1 1</scale>
        <link name='grass_plane'>
          <pose frame=''>16.2675 -10.652 0.05001 0 -0 0</pose>
          <velocity>0 0 0 0 -0 0</velocity>
          <acceleration>0 0 0 0 -0 0</acceleration>
          <wrench>0 0 0 0 -0 0</wrench>
        </link>
        <link name='link'>
          <pose frame=''>16.2675 -10.652 2 0 -0 0</pose>
          <velocity>0 0 0 0 -0 0</velocity>
          <acceleration>0 0 0 0 -0 0</acceleration>
          <wrench>0 0 0 0 -0 0</wrench>
        </link>
      </model>
      <light name='sun'>
        <pose frame=''>0 0 10 0 -0 0</pose>
      </light>
    </state>
    <gui fullscreen='0'>
      <camera name='user_camera'>
        <pose frame=''>37.9349 -29.5602 3.69514 0 0.003024 2.33688</pose>
        <view_controller>orbit</view_controller>
        <projection_type>perspective</projection_type>
      </camera>
    </gui>
    <!-- Set wind linear velocity -->
    <wind>
      <linear_velocity>0 0 0</linear_velocity>
    </wind>
    <!-- Load the plugin for the wind -->
    <plugin name="wind" filename="libWindPlugin.so">
      <horizontal>
        <magnitude>
          <time_for_rise>10</time_for_rise>
          <sin>
            <amplitude_percent>0.05</amplitude_percent>
            <period>60</period>
          </sin>
          <noise type="gaussian">
           <mean>0</mean>
           <stddev>0.0002</stddev>
          </noise>
        </magnitude>
        <direction>
          <time_for_rise>30</time_for_rise>
          <sin>
            <amplitude>5</amplitude>
            <period>20</period>
          </sin>
          <noise type="gaussian">
           <mean>0</mean>
           <stddev>0.03</stddev>
          </noise>
        </direction>
      </horizontal>
      <vertical>
        <noise type="gaussian">
         <mean>0</mean>
         <stddev>0.03</stddev>
        </noise>
      </vertical>
    </plugin>
  </world>
</sdf>
